Workbook

Sheet Inventario
A1: sku | B1: name | C1: base | D1: height | E1: presentation | F1: currentStock | G1: totalWaste | H1: minStock | I1: unitCost
A2: =_xlfn.TEXTJOIN("-",TRUE,Hoja2!A3:H3,1) -> LON-BAC-15OZ-1 | B2: LONA BACK LIT 15 OZ | C2: 1,6 | D2: 50 | E2: ROLLO
A3: =_xlfn.TEXTJOIN("-",TRUE,Hoja2!A4:H4,2) -> LON-BAC-15OZ-2 | B3: LONA BACK LIT 15 OZ | C3: 2,5 | D3: 50 | E3: ROLLO
A4: =_xlfn.TEXTJOIN("-",TRUE,Hoja2!A5:H5,3) -> LON-BAC-15OZ-3 | B4: LONA BACK LIT 15 OZ | C4: 3,2 | D4: 50 | E4: ROLLO
A5: =_xlfn.TEXTJOIN("-",TRUE,Hoja2!A6:H6,4) -> LON-FRO-13OZ-4 | B5: LONA FRONT 13 ONZAS | C5: 1,6 | D5: 50 | E5: ROLLO
A6: =_xlfn.TEXTJOIN("-",TRUE,Hoja2!A7:H7,1) -> LON-FRO-13OZ-AR-1 | B6: LONA FRONT 13 ONZAS / ALTA RESISTENCIA | C6: 2,04 | D6: 50 | E6: ROLLO
A7: =_xlfn.TEXTJOIN("-",TRUE,Hoja2!A8:H8,1) -> LON-FRO-09OZ-CA-1 | B7: LONA FRONT 9 ONZAS / CAMPAÑA | C7: 3,2 | D7: 50 | E7: ROLLO
A8: =_xlfn.TEXTJOIN("-",TRUE,Hoja2!A9:H9,2) -> LON-FRO-09OZ-CA-2 | B8: LONA FRONT 9 ONZAS / CAMPAÑA | C8: 2,04 | D8: 50 | E8: ROLLO
A9: =_xlfn.TEXTJOIN("-",TRUE,Hoja2!A10:H10,2) -> LON-FRO-13OZ-AR-2 | B9: LONA FRONT 13 ONZAS / ALTA RESISTENCIA | C9: 1,6 | D9: 50 | E9: ROLLO
A10: =_xlfn.TEXTJOIN("-",TRUE,Hoja2!A11:H11,3) -> LON-FRO-13OZ-AR-3 | B10: LONA FRONT 13 ONZAS / ALTA RESISTENCIA | C10: 2,04 | D10: 50 | E10: ROLLO
A11: =_xlfn.TEXTJOIN("-",TRUE,Hoja2!A12:H12,4) -> LON-FRO-13OZ-AR-4 | B11: LONA FRONT 13 ONZAS / ALTA RESISTENCIA | C11: 2,04 | D11: 100 | E11: ROLLO
A12: =_xlfn.TEXTJOIN("-",TRUE,Hoja2!A13:H13,5) -> LON-FRO-13OZ-AR-5 | B12: LONA FRONT 13 ONZAS / ALTA RESISTENCIA | C12: 2,5 | D12: 50 | E12: ROLLO
A13: =_xlfn.TEXTJOIN("-",TRUE,Hoja2!A14:H14,6) -> LON-FRO-13OZ-AR-6 | B13: LONA FRONT 13 ONZAS / ALTA RESISTENCIA | C13: 2,5 | D13: 100 | E13: ROLLO
A14: =_xlfn.TEXTJOIN("-",TRUE,Hoja2!A15:H15,7) -> LON-FRO-13OZ-AR-7 | B14: LONA FRONT 13 ONZAS / ALTA RESISTENCIA | C14: 3,2 | D14: 50 | E14: ROLLO
A15: =_xlfn.TEXTJOIN("-",TRUE,Hoja2!A16:H16,1) -> LON-MAT-13OZ-1 | B15: LONA MATE 13 OZ | C15: 1,6 | D15: 50 | E15: ROLLO
A16: =_xlfn.TEXTJOIN("-",TRUE,Hoja2!A17:H17,2) -> LON-MAT-13OZ-2 | B16: LONA MATE 13 OZ (PALACIO) | C16: 1,52 | D16: 50 | E16: ROLLO
A17: =_xlfn.TEXTJOIN("-",TRUE,Hoja2!A18:H18,3) -> LON-MAT-13OZ-3 | B17: LONA MATE 13 OZ | C17: 2,5 | D17: 50 | E17: ROLLO
A18: LON-MAT-13OZ-RNG-1 | B18: LONA MATE 13 OZ - RESP. NEGRO | C18: 2,5 | D18: 100 | E18: ROLLO
A19: =_xlfn.TEXTJOIN("-",TRUE,Hoja2!A20:H20,4) -> LON-MAT-13OZ-4 | B19: LONA MATE 13 OZ | C19: 3,2 | D19: 50 | E19: ROLLO
A20: LON-MAT-13OZ-RNG-2 | B20: LONA MATE 13 OZ RESP. NEGRO | C20: 3,2 | D20: 50 | E20: ROLLO
A21: LON-MAT-13OZ-RNG-3 | B21: LONA MATE 13 OZ - RESP. NEGRO | C21: 3,2 | D21: 100 | E21: ROLLO
A22: =_xlfn.TEXTJOIN("-",TRUE,Hoja2!A23:H23,1) -> LON-MES-1 | B22: LONA MESH | C22: 1,6 | D22: 50 | E22: ROLLO
A23: =_xlfn.TEXTJOIN("-",TRUE,Hoja2!A24:H24,2) -> LON-MES-2 | B23: LONA MESH | C23: 2,5 | D23: 100 | E23: ROLLO
A24: =_xlfn.TEXTJOIN("-",TRUE,Hoja2!A25:H25,3) -> LON-MES-3 | B24: LONA MESH | C24: 3,2 | D24: 50 | E24: ROLLO
A25: =_xlfn.TEXTJOIN("-",TRUE,Hoja2!A26:H26,4) -> LON-MES-4 | B25: LONA MESH | C25: 3,2 | D25: 100 | E25: ROLLO
A26: =_xlfn.TEXTJOIN("-",TRUE,Hoja2!A27:H27,"BLU") -> PAP-BAC-BLU | B26: PAPEL BLUE BACK | C26: 1,55 | D26: 50 | E26: ROLLO
A27: =_xlfn.TEXTJOIN("-",TRUE,Hoja2!A28:H28,"200G","FG") -> PAP-MAT-200G-FG | B27: PAPEL MATE 200 GRS FOTOGRAFICO | C27: 1,52 | D27: 50 | E27: ROLLO
A28: =_xlfn.TEXTJOIN("-",TRUE,Hoja2!A29:H29,"200G","FT") -> PAP-BRI-200G-FT | B28: PAPEL BRILLANTE 200 GRS FOTOGRAFICO | C28: 1,52 | D28: 50 | E28: ROLLO
A29: =_xlfn.TEXTJOIN("-",TRUE,"PAP","BAC","SMT") -> PAP-BAC-SMT | B29: PAPEL BACKLIT ( SEMIMATE) | C29: 1,52 | D29: 30 | E29: ROLLO
A30: =_xlfn.TEXTJOIN("-",TRUE,"PAP","SK") -> PAP-SK | B30: PAPEL SOLVATEX KRONALINE | C30: 1,52 | D30: 50 | E30: ROLLO
A31: =_xlfn.TEXTJOIN("-",TRUE,Hoja2!A32:H32,"CL",1) -> PAP-CL-1 | B31: PAPEL CITYLIGHT - 1.60 X 50 MTS | C31: 1,6 | D31: 50 | E31: ROLLO
A32: =_xlfn.TEXTJOIN("-",TRUE,Hoja2!A33:H33,"CL",2) -> PAP-CL-2 | B32: PAPEL CITYLIGHT - 1.60 X 50 MTS | C32: 1,6 | D32: 100 | E32: ROLLO
A33: CAR-SUL-COU-ROL | B33: CARTULINA SULFATADA (COUCHE) ROLLO | C33: 1,37 | D33: 50 | E33: ROLLO
A34: TEL-SD-1 | B34: TELA SINTETICA DELGADA | C34: 1,52 | D34: 50 | E34: ROLLO
A35: TEL-SD-2 | B35: TELA SINTETICA DELGADA | C35: 2,5 | D35: 50 | E35: ROLLO
A36: TEL-SD-3 | B36: TELA SINTETICA DELGADA | C36: 3,2 | D36: 50 | E36: ROLLO
A37: TEL-SG | B37: TELA SINTETICA GRUESA | C37: 2,5 | D37: 50 | E37: ROLLO
A38: TEL-CN-PCN | B38: TELA CANVAS - POLYCANVAS | C38: 1,52 | D38: 30 | E38: ROLLO
A39: VIN-U180-1 | B39: VINIL CONTROL TAC (IJ180) | C39: 1,52 | D39: 45,7 | E39: ROLLO
A40: VIN-U180-2 | B40: VINIL CONTROL TAC (IJ180) | C40: 1,52 | D40: 91,4 | E40: ROLLO
...

Sheet Hoja2
A3: =IF(ISNUMBER(SEARCH("LONA",Inventario!B2)),"LON", IF(ISNUMBER(SEARCH("VINIL",Inventario!B2)),"VIN", IF(ISNUMBER(SEARCH("PANEL DE ALUMINIO COMPUESTO",Inventario!B2)),"PAN-ALU-COM", IF(ISNUMBER(SEARCH("PVC",Inventario!B2)),"PVC", IF(ISNUMBER(SEARCH("PAPEL",Inventario!B2)),"PAP", IF(ISNUMBER(SEARCH("TELA",Inventario!B2)),"TEL", IF(ISNUMBER(SEARCH("CARTULINA",Inventario!B2)),"CAR", IF(OR(ISNUMBER(SEARCH("LAMINA",Inventario!B2)),ISNUMBER(SEARCH("LÁMINA",Inventario!B2))),"LAM", IF(ISNUMBER(SEARCH("ESTIRENO",Inventario!B2)),"EST", IF(ISNUMBER(SEARCH("FOAMBOARD",Inventario!B2)),"FOA", IF(ISNUMBER(SEARCH("SOLVENTE",Inventario!B2)),"SOL", IF(ISNUMBER(SEARCH("TINTA",Inventario!B2)),"TIN", IF(ISNUMBER(SEARCH("ACRILICO",Inventario!B2)),"ACR", IF(ISNUMBER(SEARCH("LED",Inventario!B2)),"LED", IF(ISNUMBER(SEARCH("FUENTE",Inventario!B2)),"FUE", IF(ISNUMBER(SEARCH("PETG",Inventario!B2)),"PET", IF(ISNUMBER(SEARCH("ALUMINIO",Inventario!B2)),"ALU", IF(ISNUMBER(SEARCH("CANAL",Inventario!B2)),"CAN", IF(ISNUMBER(SEARCH("ESCUADRA",Inventario!B2)),"ESC", IF(ISNUMBER(SEARCH("SOPORTE",Inventario!B2)),"SOP","OTR") ))))))))))))))))))) -> LON | B3: =IF(ISNUMBER(SEARCH("CORTE",Inventario!B2)),"COR", IF(ISNUMBER(SEARCH("CRISTAL",Inventario!B2)),"CR", IF(OR(ISNUMBER(SEARCH("OPTICO",Inventario!B2)),ISNUMBER(SEARCH("OPTICOS",Inventario!B2)),ISNUMBER(SEARCH("OPTICA",Inventario!B2))),"OP", IF(ISNUMBER(SEARCH("NANO",Inventario!B2)),"NA", IF(ISNUMBER(SEARCH("5050",Inventario!B2)),"5050", IF(ISNUMBER(SEARCH("MICRO",Inventario!B2)),"MI","")))))) | C3: =IF(ISNUMBER(SEARCH("PARED",Inventario!B2)),"PAR",IF(ISNUMBER(SEARCH("MATE",Inventario!B2)),"MAT", IF(ISNUMBER(SEARCH("FRONT",Inventario!B2)),"FRO", IF(ISNUMBER(SEARCH("BACK",Inventario!B2)),"BAC", IF(ISNUMBER(SEARCH("MESH",Inventario!B2)),"MES", IF(OR(ISNUMBER(SEARCH("BRILLANTE",Inventario!B2)),ISNUMBER(SEARCH("BTE",Inventario!B2))),"BRI", IF(ISNUMBER(SEARCH("SINTETICA DELGADA",Inventario!B2)),"SD", IF(ISNUMBER(SEARCH("SINTETICA GRUESA",Inventario!B2)),"SG", IF(ISNUMBER(SEARCH("ESTATICO",Inventario!B2)),"EST", IF(ISNUMBER(SEARCH("FLOOR",Inventario!B2)),"FLO", IF(ISNUMBER(SEARCH("REFLECTIVO",Inventario!B2)),"REF", IF(ISNUMBER(SEARCH("MICROPERFORADO",Inventario!B2)),"MI", IF(ISNUMBER(SEARCH("CEPILLADO",Inventario!B2)),"CEP", IF(ISNUMBER(SEARCH("ESPEJO",Inventario!B2)),"ESP", IF(OR(ISNUMBER(SEARCH("UNIDIODO",Inventario!B2)),ISNUMBER(SEARCH("1 DIODO",Inventario!B2))),"1D", IF(ISNUMBER(SEARCH("2 DIODOS",Inventario!B2)),"2D", IF(ISNUMBER(SEARCH("3 DIODOS",Inventario!B2)),"3D",""))))))))))))))))) -> BAC | D3: =IF(ISNUMBER(SEARCH("LX700",Inventario!B2)),"LX7", IF(ISNUMBER(SEARCH("GRANDO",Inventario!B2)),"GRA", IF(OR(ISNUMBER(SEARCH("CAMA PLANA",Inventario!B2)),ISNUMBER(SEARCH("FB700",Inventario!B2))),"CP", IF(ISNUMBER(SEARCH("LX360",Inventario!B2)),"LX3", IF(ISNUMBER(SEARCH("XEROX",Inventario!B2)),"XER", IF(ISNUMBER(SEARCH("18 OZ",Inventario!B2)),"18OZ", IF(ISNUMBER(SEARCH("15 OZ",Inventario!B2)),"15OZ", IF(OR(ISNUMBER(SEARCH("13 OZ",Inventario!B2)),ISNUMBER(SEARCH("13 ONZAS",Inventario!B2))),"13OZ", IF(OR(ISNUMBER(SEARCH("9 OZ",Inventario!B2)),ISNUMBER(SEARCH("9 ONZAS",Inventario!B2))),"09OZ",""))))))))) -> 15OZ | E3: =IF(OR(ISNUMBER(SEARCH("TRANSPARENTE",Inventario!B2)),ISNUMBER(SEARCH("TRANSPARENTES",Inventario!B2))),"TR", IF(OR(ISNUMBER(SEARCH("BLANCO",Inventario!B2)),ISNUMBER(SEARCH("BCO",Inventario!B2))),"BL", IF(ISNUMBER(SEARCH("VERDE",Inventario!B2)),"VR", IF(ISNUMBER(SEARCH("MORADO",Inventario!B2)),"MR", IF(ISNUMBER(SEARCH("PLATA",Inventario!B2)),"PL", IF(ISNUMBER(SEARCH("ORO",Inventario!B2)),"OR", IF(ISNUMBER(SEARCH("AMARILLO",Inventario!B2)),"AM", IF(ISNUMBER(SEARCH("NARANJA",Inventario!B2)),"NR", IF(ISNUMBER(SEARCH("NEGRO",Inventario!B2)),"NG", IF(ISNUMBER(SEARCH("ROJO",Inventario!B2)),"RJ", IF(ISNUMBER(SEARCH("AZUL",Inventario!B2)),"AZ",""))))))))))) | F3: =IF(ISNUMBER(SEARCH("1,2 MM",Inventario!B2)),"1MM2", IF(OR(ISNUMBER(SEARCH("2 MM",Inventario!B2)),ISNUMBER(SEARCH("2MM",Inventario!B2))),"2MM", IF(OR(ISNUMBER(SEARCH("3 MM",Inventario!B2)),ISNUMBER(SEARCH("3MM",Inventario!B2))),"3MM", IF(OR(ISNUMBER(SEARCH("4 MM",Inventario!B2)),ISNUMBER(SEARCH("4MM",Inventario!B2)),ISNUMBER(SEARCH("4 mm",Inventario!B2))),"4MM", IF(OR(ISNUMBER(SEARCH("5 MM",Inventario!B2)),ISNUMBER(SEARCH("5MM",Inventario!B2))),"5MM", IF(OR(ISNUMBER(SEARCH("6 MM",Inventario!B2)),ISNUMBER(SEARCH("6MM",Inventario!B2))),"6MM", IF(OR(ISNUMBER(SEARCH("10 MM",Inventario!B2)),ISNUMBER(SEARCH("10MM",Inventario!B2))),"10MM",""))))))) | G3: =IF(ISNUMBER(SEARCH("ALTA RESISTENCIA",Inventario!B2)),"AR",IF(ISNUMBER(SEARCH("CAMPAÑA",Inventario!B2)),"CA", IF(OR(ISNUMBER(SEARCH("CALIDO",Inventario!B2)),ISNUMBER(SEARCH("CÁLIDO",Inventario!B2))),"C", IF(OR(ISNUMBER(SEARCH("TRASLUCIDO",Inventario!B2)),ISNUMBER(SEARCH("TRANSLUCIDO",Inventario!B2))),"TL", IF(ISNUMBER(SEARCH("NEUTRO",Inventario!B2)),"N", IF(ISNUMBER(SEARCH("FRIO",Inventario!B2)),"F","")))))) | H3: =IF(ISNUMBER(SEARCH("SILED",Inventario!B2)),"SI", IF(ISNUMBER(SEARCH("SYDEMEX",Inventario!B2)),"SY", IF(ISNUMBER(SEARCH("ROHS",Inventario!B2)),"RO", IF(ISNUMBER(SEARCH("RISHANG",Inventario!B2)),"RS", IF(ISNUMBER(SEARCH("VYG",Inventario!B2)),"VYG", IF(ISNUMBER(SEARCH("COLED",Inventario!B2)),"CO",""))))))
A4: =IF(ISNUMBER(SEARCH("LONA",Inventario!B3)),"LON", IF(ISNUMBER(SEARCH("VINIL",Inventario!B3)),"VIN", IF(ISNUMBER(SEARCH("PANEL DE ALUMINIO COMPUESTO",Inventario!B3)),"PAN-ALU-COM", IF(ISNUMBER(SEARCH("PVC",Inventario!B3)),"PVC", IF(ISNUMBER(SEARCH("PAPEL",Inventario!B3)),"PAP", IF(ISNUMBER(SEARCH("TELA",Inventario!B3)),"TEL", IF(ISNUMBER(SEARCH("CARTULINA",Inventario!B3)),"CAR", IF(OR(ISNUMBER(SEARCH("LAMINA",Inventario!B3)),ISNUMBER(SEARCH("LÁMINA",Inventario!B3))),"LAM", IF(ISNUMBER(SEARCH("ESTIRENO",Inventario!B3)),"EST", IF(ISNUMBER(SEARCH("FOAMBOARD",Inventario!B3)),"FOA", IF(ISNUMBER(SEARCH("SOLVENTE",Inventario!B3)),"SOL", IF(ISNUMBER(SEARCH("TINTA",Inventario!B3)),"TIN", IF(ISNUMBER(SEARCH("ACRILICO",Inventario!B3)),"ACR", IF(ISNUMBER(SEARCH("LED",Inventario!B3)),"LED", IF(ISNUMBER(SEARCH("FUENTE",Inventario!B3)),"FUE", IF(ISNUMBER(SEARCH("PETG",Inventario!B3)),"PET", IF(ISNUMBER(SEARCH("ALUMINIO",Inventario!B3)),"ALU", IF(ISNUMBER(SEARCH("CANAL",Inventario!B3)),"CAN", IF(ISNUMBER(SEARCH("ESCUADRA",Inventario!B3)),"ESC", IF(ISNUMBER(SEARCH("SOPORTE",Inventario!B3)),"SOP","OTR") ))))))))))))))))))) -> LON | B4: =IF(ISNUMBER(SEARCH("CORTE",Inventario!B3)),"COR", IF(ISNUMBER(SEARCH("CRISTAL",Inventario!B3)),"CR", IF(OR(ISNUMBER(SEARCH("OPTICO",Inventario!B3)),ISNUMBER(SEARCH("OPTICOS",Inventario!B3)),ISNUMBER(SEARCH("OPTICA",Inventario!B3))),"OP", IF(ISNUMBER(SEARCH("NANO",Inventario!B3)),"NA", IF(ISNUMBER(SEARCH("5050",Inventario!B3)),"5050", IF(ISNUMBER(SEARCH("MICRO",Inventario!B3)),"MI","")))))) | C4: =IF(ISNUMBER(SEARCH("PARED",Inventario!B3)),"PAR",IF(ISNUMBER(SEARCH("MATE",Inventario!B3)),"MAT", IF(ISNUMBER(SEARCH("FRONT",Inventario!B3)),"FRO", IF(ISNUMBER(SEARCH("BACK",Inventario!B3)),"BAC", IF(ISNUMBER(SEARCH("MESH",Inventario!B3)),"MES", IF(OR(ISNUMBER(SEARCH("BRILLANTE",Inventario!B3)),ISNUMBER(SEARCH("BTE",Inventario!B3))),"BRI", IF(ISNUMBER(SEARCH("SINTETICA DELGADA",Inventario!B3)),"SD", IF(ISNUMBER(SEARCH("SINTETICA GRUESA",Inventario!B3)),"SG", IF(ISNUMBER(SEARCH("ESTATICO",Inventario!B3)),"EST", IF(ISNUMBER(SEARCH("FLOOR",Inventario!B3)),"FLO", IF(ISNUMBER(SEARCH("REFLECTIVO",Inventario!B3)),"REF", IF(ISNUMBER(SEARCH("MICROPERFORADO",Inventario!B3)),"MI", IF(ISNUMBER(SEARCH("CEPILLADO",Inventario!B3)),"CEP", IF(ISNUMBER(SEARCH("ESPEJO",Inventario!B3)),"ESP", IF(OR(ISNUMBER(SEARCH("UNIDIODO",Inventario!B3)),ISNUMBER(SEARCH("1 DIODO",Inventario!B3))),"1D", IF(ISNUMBER(SEARCH("2 DIODOS",Inventario!B3)),"2D", IF(ISNUMBER(SEARCH("3 DIODOS",Inventario!B3)),"3D",""))))))))))))))))) -> BAC | D4: =IF(ISNUMBER(SEARCH("LX700",Inventario!B3)),"LX7", IF(ISNUMBER(SEARCH("GRANDO",Inventario!B3)),"GRA", IF(OR(ISNUMBER(SEARCH("CAMA PLANA",Inventario!B3)),ISNUMBER(SEARCH("FB700",Inventario!B3))),"CP", IF(ISNUMBER(SEARCH("LX360",Inventario!B3)),"LX3", IF(ISNUMBER(SEARCH("XEROX",Inventario!B3)),"XER", IF(ISNUMBER(SEARCH("18 OZ",Inventario!B3)),"18OZ", IF(ISNUMBER(SEARCH("15 OZ",Inventario!B3)),"15OZ", IF(OR(ISNUMBER(SEARCH("13 OZ",Inventario!B3)),ISNUMBER(SEARCH("13 ONZAS",Inventario!B3))),"13OZ", IF(OR(ISNUMBER(SEARCH("9 OZ",Inventario!B3)),ISNUMBER(SEARCH("9 ONZAS",Inventario!B3))),"09OZ",""))))))))) -> 15OZ | E4: =IF(OR(ISNUMBER(SEARCH("TRANSPARENTE",Inventario!B3)),ISNUMBER(SEARCH("TRANSPARENTES",Inventario!B3))),"TR", IF(OR(ISNUMBER(SEARCH("BLANCO",Inventario!B3)),ISNUMBER(SEARCH("BCO",Inventario!B3))),"BL", IF(ISNUMBER(SEARCH("VERDE",Inventario!B3)),"VR", IF(ISNUMBER(SEARCH("MORADO",Inventario!B3)),"MR", IF(ISNUMBER(SEARCH("PLATA",Inventario!B3)),"PL", IF(ISNUMBER(SEARCH("ORO",Inventario!B3)),"OR", IF(ISNUMBER(SEARCH("AMARILLO",Inventario!B3)),"AM", IF(ISNUMBER(SEARCH("NARANJA",Inventario!B3)),"NR", IF(ISNUMBER(SEARCH("NEGRO",Inventario!B3)),"NG", IF(ISNUMBER(SEARCH("ROJO",Inventario!B3)),"RJ", IF(ISNUMBER(SEARCH("AZUL",Inventario!B3)),"AZ",""))))))))))) | F4: =IF(ISNUMBER(SEARCH("1,2 MM",Inventario!B3)),"1MM2", IF(OR(ISNUMBER(SEARCH("2 MM",Inventario!B3)),ISNUMBER(SEARCH("2MM",Inventario!B3))),"2MM", IF(OR(ISNUMBER(SEARCH("3 MM",Inventario!B3)),ISNUMBER(SEARCH("3MM",Inventario!B3))),"3MM", IF(OR(ISNUMBER(SEARCH("4 MM",Inventario!B3)),ISNUMBER(SEARCH("4MM",Inventario!B3)),ISNUMBER(SEARCH("4 mm",Inventario!B3))),"4MM", IF(OR(ISNUMBER(SEARCH("5 MM",Inventario!B3)),ISNUMBER(SEARCH("5MM",Inventario!B3))),"5MM", IF(OR(ISNUMBER(SEARCH("6 MM",Inventario!B3)),ISNUMBER(SEARCH("6MM",Inventario!B3))),"6MM", IF(OR(ISNUMBER(SEARCH("10 MM",Inventario!B3)),ISNUMBER(SEARCH("10MM",Inventario!B3))),"10MM",""))))))) | G4: =IF(ISNUMBER(SEARCH("ALTA RESISTENCIA",Inventario!B3)),"AR",IF(ISNUMBER(SEARCH("CAMPAÑA",Inventario!B3)),"CA", IF(OR(ISNUMBER(SEARCH("CALIDO",Inventario!B3)),ISNUMBER(SEARCH("CÁLIDO",Inventario!B3))),"C", IF(OR(ISNUMBER(SEARCH("TRASLUCIDO",Inventario!B3)),ISNUMBER(SEARCH("TRANSLUCIDO",Inventario!B3))),"TL", IF(ISNUMBER(SEARCH("NEUTRO",Inventario!B3)),"N", IF(ISNUMBER(SEARCH("FRIO",Inventario!B3)),"F","")))))) | H4: =IF(ISNUMBER(SEARCH("SILED",Inventario!B3)),"SI", IF(ISNUMBER(SEARCH("SYDEMEX",Inventario!B3)),"SY", IF(ISNUMBER(SEARCH("ROHS",Inventario!B3)),"RO", IF(ISNUMBER(SEARCH("RISHANG",Inventario!B3)),"RS", IF(ISNUMBER(SEARCH("VYG",Inventario!B3)),"VYG", IF(ISNUMBER(SEARCH("COLED",Inventario!B3)),"CO",""))))))
A5: =IF(ISNUMBER(SEARCH("LONA",Inventario!B4)),"LON", IF(ISNUMBER(SEARCH("VINIL",Inventario!B4)),"VIN", IF(ISNUMBER(SEARCH("PANEL DE ALUMINIO COMPUESTO",Inventario!B4)),"PAN-ALU-COM", IF(ISNUMBER(SEARCH("PVC",Inventario!B4)),"PVC", IF(ISNUMBER(SEARCH("PAPEL",Inventario!B4)),"PAP", IF(ISNUMBER(SEARCH("TELA",Inventario!B4)),"TEL", IF(ISNUMBER(SEARCH("CARTULINA",Inventario!B4)),"CAR", IF(OR(ISNUMBER(SEARCH("LAMINA",Inventario!B4)),ISNUMBER(SEARCH("LÁMINA",Inventario!B4))),"LAM", IF(ISNUMBER(SEARCH("ESTIRENO",Inventario!B4)),"EST", IF(ISNUMBER(SEARCH("FOAMBOARD",Inventario!B4)),"FOA", IF(ISNUMBER(SEARCH("SOLVENTE",Inventario!B4)),"SOL", IF(ISNUMBER(SEARCH("TINTA",Inventario!B4)),"TIN", IF(ISNUMBER(SEARCH("ACRILICO",Inventario!B4)),"ACR", IF(ISNUMBER(SEARCH("LED",Inventario!B4)),"LED", IF(ISNUMBER(SEARCH("FUENTE",Inventario!B4)),"FUE", IF(ISNUMBER(SEARCH("PETG",Inventario!B4)),"PET", IF(ISNUMBER(SEARCH("ALUMINIO",Inventario!B4)),"ALU", IF(ISNUMBER(SEARCH("CANAL",Inventario!B4)),"CAN", IF(ISNUMBER(SEARCH("ESCUADRA",Inventario!B4)),"ESC", IF(ISNUMBER(SEARCH("SOPORTE",Inventario!B4)),"SOP","OTR") ))))))))))))))))))) -> LON | B5: =IF(ISNUMBER(SEARCH("CORTE",Inventario!B4)),"COR", IF(ISNUMBER(SEARCH("CRISTAL",Inventario!B4)),"CR", IF(OR(ISNUMBER(SEARCH("OPTICO",Inventario!B4)),ISNUMBER(SEARCH("OPTICOS",Inventario!B4)),ISNUMBER(SEARCH("OPTICA",Inventario!B4))),"OP", IF(ISNUMBER(SEARCH("NANO",Inventario!B4)),"NA", IF(ISNUMBER(SEARCH("5050",Inventario!B4)),"5050", IF(ISNUMBER(SEARCH("MICRO",Inventario!B4)),"MI","")))))) | C5: =IF(ISNUMBER(SEARCH("PARED",Inventario!B4)),"PAR",IF(ISNUMBER(SEARCH("MATE",Inventario!B4)),"MAT", IF(ISNUMBER(SEARCH("FRONT",Inventario!B4)),"FRO", IF(ISNUMBER(SEARCH("BACK",Inventario!B4)),"BAC", IF(ISNUMBER(SEARCH("MESH",Inventario!B4)),"MES", IF(OR(ISNUMBER(SEARCH("BRILLANTE",Inventario!B4)),ISNUMBER(SEARCH("BTE",Inventario!B4))),"BRI", IF(ISNUMBER(SEARCH("SINTETICA DELGADA",Inventario!B4)),"SD", IF(ISNUMBER(SEARCH("SINTETICA GRUESA",Inventario!B4)),"SG", IF(ISNUMBER(SEARCH("ESTATICO",Inventario!B4)),"EST", IF(ISNUMBER(SEARCH("FLOOR",Inventario!B4)),"FLO", IF(ISNUMBER(SEARCH("REFLECTIVO",Inventario!B4)),"REF", IF(ISNUMBER(SEARCH("MICROPERFORADO",Inventario!B4)),"MI", IF(ISNUMBER(SEARCH("CEPILLADO",Inventario!B4)),"CEP", IF(ISNUMBER(SEARCH("ESPEJO",Inventario!B4)),"ESP", IF(OR(ISNUMBER(SEARCH("UNIDIODO",Inventario!B4)),ISNUMBER(SEARCH("1 DIODO",Inventario!B4))),"1D", IF(ISNUMBER(SEARCH("2 DIODOS",Inventario!B4)),"2D", IF(ISNUMBER(SEARCH("3 DIODOS",Inventario!B4)),"3D",""))))))))))))))))) -> BAC | D5: =IF(ISNUMBER(SEARCH("LX700",Inventario!B4)),"LX7", IF(ISNUMBER(SEARCH("GRANDO",Inventario!B4)),"GRA", IF(OR(ISNUMBER(SEARCH("CAMA PLANA",Inventario!B4)),ISNUMBER(SEARCH("FB700",Inventario!B4))),"CP", IF(ISNUMBER(SEARCH("LX360",Inventario!B4)),"LX3", IF(ISNUMBER(SEARCH("XEROX",Inventario!B4)),"XER", IF(ISNUMBER(SEARCH("18 OZ",Inventario!B4)),"18OZ", IF(ISNUMBER(SEARCH("15 OZ",Inventario!B4)),"15OZ", IF(OR(ISNUMBER(SEARCH("13 OZ",Inventario!B4)),ISNUMBER(SEARCH("13 ONZAS",Inventario!B4))),"13OZ", IF(OR(ISNUMBER(SEARCH("9 OZ",Inventario!B4)),ISNUMBER(SEARCH("9 ONZAS",Inventario!B4))),"09OZ",""))))))))) -> 15OZ | E5: =IF(OR(ISNUMBER(SEARCH("TRANSPARENTE",Inventario!B4)),ISNUMBER(SEARCH("TRANSPARENTES",Inventario!B4))),"TR", IF(OR(ISNUMBER(SEARCH("BLANCO",Inventario!B4)),ISNUMBER(SEARCH("BCO",Inventario!B4))),"BL", IF(ISNUMBER(SEARCH("VERDE",Inventario!B4)),"VR", IF(ISNUMBER(SEARCH("MORADO",Inventario!B4)),"MR", IF(ISNUMBER(SEARCH("PLATA",Inventario!B4)),"PL", IF(ISNUMBER(SEARCH("ORO",Inventario!B4)),"OR", IF(ISNUMBER(SEARCH("AMARILLO",Inventario!B4)),"AM", IF(ISNUMBER(SEARCH("NARANJA",Inventario!B4)),"NR", IF(ISNUMBER(SEARCH("NEGRO",Inventario!B4)),"NG", IF(ISNUMBER(SEARCH("ROJO",Inventario!B4)),"RJ", IF(ISNUMBER(SEARCH("AZUL",Inventario!B4)),"AZ",""))))))))))) | F5: =IF(ISNUMBER(SEARCH("1,2 MM",Inventario!B4)),"1MM2", IF(OR(ISNUMBER(SEARCH("2 MM",Inventario!B4)),ISNUMBER(SEARCH("2MM",Inventario!B4))),"2MM", IF(OR(ISNUMBER(SEARCH("3 MM",Inventario!B4)),ISNUMBER(SEARCH("3MM",Inventario!B4))),"3MM", IF(OR(ISNUMBER(SEARCH("4 MM",Inventario!B4)),ISNUMBER(SEARCH("4MM",Inventario!B4)),ISNUMBER(SEARCH("4 mm",Inventario!B4))),"4MM", IF(OR(ISNUMBER(SEARCH("5 MM",Inventario!B4)),ISNUMBER(SEARCH("5MM",Inventario!B4))),"5MM", IF(OR(ISNUMBER(SEARCH("6 MM",Inventario!B4)),ISNUMBER(SEARCH("6MM",Inventario!B4))),"6MM", IF(OR(ISNUMBER(SEARCH("10 MM",Inventario!B4)),ISNUMBER(SEARCH("10MM",Inventario!B4))),"10MM",""))))))) | G5: =IF(ISNUMBER(SEARCH("ALTA RESISTENCIA",Inventario!B4)),"AR",IF(ISNUMBER(SEARCH("CAMPAÑA",Inventario!B4)),"CA", IF(OR(ISNUMBER(SEARCH("CALIDO",Inventario!B4)),ISNUMBER(SEARCH("CÁLIDO",Inventario!B4))),"C", IF(OR(ISNUMBER(SEARCH("TRASLUCIDO",Inventario!B4)),ISNUMBER(SEARCH("TRANSLUCIDO",Inventario!B4))),"TL", IF(ISNUMBER(SEARCH("NEUTRO",Inventario!B4)),"N", IF(ISNUMBER(SEARCH("FRIO",Inventario!B4)),"F","")))))) | H5: =IF(ISNUMBER(SEARCH("SILED",Inventario!B4)),"SI", IF(ISNUMBER(SEARCH("SYDEMEX",Inventario!B4)),"SY", IF(ISNUMBER(SEARCH("ROHS",Inventario!B4)),"RO", IF(ISNUMBER(SEARCH("RISHANG",Inventario!B4)),"RS", IF(ISNUMBER(SEARCH("VYG",Inventario!B4)),"VYG", IF(ISNUMBER(SEARCH("COLED",Inventario!B4)),"CO",""))))))
A6: =IF(ISNUMBER(SEARCH("LONA",Inventario!B5)),"LON", IF(ISNUMBER(SEARCH("VINIL",Inventario!B5)),"VIN", IF(ISNUMBER(SEARCH("PANEL DE ALUMINIO COMPUESTO",Inventario!B5)),"PAN-ALU-COM", IF(ISNUMBER(SEARCH("PVC",Inventario!B5)),"PVC", IF(ISNUMBER(SEARCH("PAPEL",Inventario!B5)),"PAP", IF(ISNUMBER(SEARCH("TELA",Inventario!B5)),"TEL", IF(ISNUMBER(SEARCH("CARTULINA",Inventario!B5)),"CAR", IF(OR(ISNUMBER(SEARCH("LAMINA",Inventario!B5)),ISNUMBER(SEARCH("LÁMINA",Inventario!B5))),"LAM", IF(ISNUMBER(SEARCH("ESTIRENO",Inventario!B5)),"EST", IF(ISNUMBER(SEARCH("FOAMBOARD",Inventario!B5)),"FOA", IF(ISNUMBER(SEARCH("SOLVENTE",Inventario!B5)),"SOL", IF(ISNUMBER(SEARCH("TINTA",Inventario!B5)),"TIN", IF(ISNUMBER(SEARCH("ACRILICO",Inventario!B5)),"ACR", IF(ISNUMBER(SEARCH("LED",Inventario!B5)),"LED", IF(ISNUMBER(SEARCH("FUENTE",Inventario!B5)),"FUE", IF(ISNUMBER(SEARCH("PETG",Inventario!B5)),"PET", IF(ISNUMBER(SEARCH("ALUMINIO",Inventario!B5)),"ALU", IF(ISNUMBER(SEARCH("CANAL",Inventario!B5)),"CAN", IF(ISNUMBER(SEARCH("ESCUADRA",Inventario!B5)),"ESC", IF(ISNUMBER(SEARCH("SOPORTE",Inventario!B5)),"SOP","OTR") ))))))))))))))))))) -> LON | B6: =IF(ISNUMBER(SEARCH("CORTE",Inventario!B5)),"COR", IF(ISNUMBER(SEARCH("CRISTAL",Inventario!B5)),"CR", IF(OR(ISNUMBER(SEARCH("OPTICO",Inventario!B5)),ISNUMBER(SEARCH("OPTICOS",Inventario!B5)),ISNUMBER(SEARCH("OPTICA",Inventario!B5))),"OP", IF(ISNUMBER(SEARCH("NANO",Inventario!B5)),"NA", IF(ISNUMBER(SEARCH("5050",Inventario!B5)),"5050", IF(ISNUMBER(SEARCH("MICRO",Inventario!B5)),"MI","")))))) | C6: =IF(ISNUMBER(SEARCH("PARED",Inventario!B5)),"PAR",IF(ISNUMBER(SEARCH("MATE",Inventario!B5)),"MAT", IF(ISNUMBER(SEARCH("FRONT",Inventario!B5)),"FRO", IF(ISNUMBER(SEARCH("BACK",Inventario!B5)),"BAC", IF(ISNUMBER(SEARCH("MESH",Inventario!B5)),"MES", IF(OR(ISNUMBER(SEARCH("BRILLANTE",Inventario!B5)),ISNUMBER(SEARCH("BTE",Inventario!B5))),"BRI", IF(ISNUMBER(SEARCH("SINTETICA DELGADA",Inventario!B5)),"SD", IF(ISNUMBER(SEARCH("SINTETICA GRUESA",Inventario!B5)),"SG", IF(ISNUMBER(SEARCH("ESTATICO",Inventario!B5)),"EST", IF(ISNUMBER(SEARCH("FLOOR",Inventario!B5)),"FLO", IF(ISNUMBER(SEARCH("REFLECTIVO",Inventario!B5)),"REF", IF(ISNUMBER(SEARCH("MICROPERFORADO",Inventario!B5)),"MI", IF(ISNUMBER(SEARCH("CEPILLADO",Inventario!B5)),"CEP", IF(ISNUMBER(SEARCH("ESPEJO",Inventario!B5)),"ESP", IF(OR(ISNUMBER(SEARCH("UNIDIODO",Inventario!B5)),ISNUMBER(SEARCH("1 DIODO",Inventario!B5))),"1D", IF(ISNUMBER(SEARCH("2 DIODOS",Inventario!B5)),"2D", IF(ISNUMBER(SEARCH("3 DIODOS",Inventario!B5)),"3D",""))))))))))))))))) -> FRO | D6: =IF(ISNUMBER(SEARCH("LX700",Inventario!B5)),"LX7", IF(ISNUMBER(SEARCH("GRANDO",Inventario!B5)),"GRA", IF(OR(ISNUMBER(SEARCH("CAMA PLANA",Inventario!B5)),ISNUMBER(SEARCH("FB700",Inventario!B5))),"CP", IF(ISNUMBER(SEARCH("LX360",Inventario!B5)),"LX3", IF(ISNUMBER(SEARCH("XEROX",Inventario!B5)),"XER", IF(ISNUMBER(SEARCH("18 OZ",Inventario!B5)),"18OZ", IF(ISNUMBER(SEARCH("15 OZ",Inventario!B5)),"15OZ", IF(OR(ISNUMBER(SEARCH("13 OZ",Inventario!B5)),ISNUMBER(SEARCH("13 ONZAS",Inventario!B5))),"13OZ", IF(OR(ISNUMBER(SEARCH("9 OZ",Inventario!B5)),ISNUMBER(SEARCH("9 ONZAS",Inventario!B5))),"09OZ",""))))))))) -> 13OZ | E6: =IF(OR(ISNUMBER(SEARCH("TRANSPARENTE",Inventario!B5)),ISNUMBER(SEARCH("TRANSPARENTES",Inventario!B5))),"TR", IF(OR(ISNUMBER(SEARCH("BLANCO",Inventario!B5)),ISNUMBER(SEARCH("BCO",Inventario!B5))),"BL", IF(ISNUMBER(SEARCH("VERDE",Inventario!B5)),"VR", IF(ISNUMBER(SEARCH("MORADO",Inventario!B5)),"MR", IF(ISNUMBER(SEARCH("PLATA",Inventario!B5)),"PL", IF(ISNUMBER(SEARCH("ORO",Inventario!B5)),"OR", IF(ISNUMBER(SEARCH("AMARILLO",Inventario!B5)),"AM", IF(ISNUMBER(SEARCH("NARANJA",Inventario!B5)),"NR", IF(ISNUMBER(SEARCH("NEGRO",Inventario!B5)),"NG", IF(ISNUMBER(SEARCH("ROJO",Inventario!B5)),"RJ", IF(ISNUMBER(SEARCH("AZUL",Inventario!B5)),"AZ",""))))))))))) | F6: =IF(ISNUMBER(SEARCH("1,2 MM",Inventario!B5)),"1MM2", IF(OR(ISNUMBER(SEARCH("2 MM",Inventario!B5)),ISNUMBER(SEARCH("2MM",Inventario!B5))),"2MM", IF(OR(ISNUMBER(SEARCH("3 MM",Inventario!B5)),ISNUMBER(SEARCH("3MM",Inventario!B5))),"3MM", IF(OR(ISNUMBER(SEARCH("4 MM",Inventario!B5)),ISNUMBER(SEARCH("4MM",Inventario!B5)),ISNUMBER(SEARCH("4 mm",Inventario!B5))),"4MM", IF(OR(ISNUMBER(SEARCH("5 MM",Inventario!B5)),ISNUMBER(SEARCH("5MM",Inventario!B5))),"5MM", IF(OR(ISNUMBER(SEARCH("6 MM",Inventario!B5)),ISNUMBER(SEARCH("6MM",Inventario!B5))),"6MM", IF(OR(ISNUMBER(SEARCH("10 MM",Inventario!B5)),ISNUMBER(SEARCH("10MM",Inventario!B5))),"10MM",""))))))) | G6: =IF(ISNUMBER(SEARCH("ALTA RESISTENCIA",Inventario!B5)),"AR",IF(ISNUMBER(SEARCH("CAMPAÑA",Inventario!B5)),"CA", IF(OR(ISNUMBER(SEARCH("CALIDO",Inventario!B5)),ISNUMBER(SEARCH("CÁLIDO",Inventario!B5))),"C", IF(OR(ISNUMBER(SEARCH("TRASLUCIDO",Inventario!B5)),ISNUMBER(SEARCH("TRANSLUCIDO",Inventario!B5))),"TL", IF(ISNUMBER(SEARCH("NEUTRO",Inventario!B5)),"N", IF(ISNUMBER(SEARCH("FRIO",Inventario!B5)),"F","")))))) | H6: =IF(ISNUMBER(SEARCH("SILED",Inventario!B5)),"SI", IF(ISNUMBER(SEARCH("SYDEMEX",Inventario!B5)),"SY", IF(ISNUMBER(SEARCH("ROHS",Inventario!B5)),"RO", IF(ISNUMBER(SEARCH("RISHANG",Inventario!B5)),"RS", IF(ISNUMBER(SEARCH("VYG",Inventario!B5)),"VYG", IF(ISNUMBER(SEARCH("COLED",Inventario!B5)),"CO",""))))))
A7: =IF(ISNUMBER(SEARCH("LONA",Inventario!B6)),"LON", IF(ISNUMBER(SEARCH("VINIL",Inventario!B6)),"VIN", IF(ISNUMBER(SEARCH("PANEL DE ALUMINIO COMPUESTO",Inventario!B6)),"PAN-ALU-COM", IF(ISNUMBER(SEARCH("PVC",Inventario!B6)),"PVC", IF(ISNUMBER(SEARCH("PAPEL",Inventario!B6)),"PAP", IF(ISNUMBER(SEARCH("TELA",Inventario!B6)),"TEL", IF(ISNUMBER(SEARCH("CARTULINA",Inventario!B6)),"CAR", IF(OR(ISNUMBER(SEARCH("LAMINA",Inventario!B6)),ISNUMBER(SEARCH("LÁMINA",Inventario!B6))),"LAM", IF(ISNUMBER(SEARCH("ESTIRENO",Inventario!B6)),"EST", IF(ISNUMBER(SEARCH("FOAMBOARD",Inventario!B6)),"FOA", IF(ISNUMBER(SEARCH("SOLVENTE",Inventario!B6)),"SOL", IF(ISNUMBER(SEARCH("TINTA",Inventario!B6)),"TIN", IF(ISNUMBER(SEARCH("ACRILICO",Inventario!B6)),"ACR", IF(ISNUMBER(SEARCH("LED",Inventario!B6)),"LED", IF(ISNUMBER(SEARCH("FUENTE",Inventario!B6)),"FUE", IF(ISNUMBER(SEARCH("PETG",Inventario!B6)),"PET", IF(ISNUMBER(SEARCH("ALUMINIO",Inventario!B6)),"ALU", IF(ISNUMBER(SEARCH("CANAL",Inventario!B6)),"CAN", IF(ISNUMBER(SEARCH("ESCUADRA",Inventario!B6)),"ESC", IF(ISNUMBER(SEARCH("SOPORTE",Inventario!B6)),"SOP","OTR") ))))))))))))))))))) -> LON | B7: =IF(ISNUMBER(SEARCH("CORTE",Inventario!B6)),"COR", IF(ISNUMBER(SEARCH("CRISTAL",Inventario!B6)),"CR", IF(OR(ISNUMBER(SEARCH("OPTICO",Inventario!B6)),ISNUMBER(SEARCH("OPTICOS",Inventario!B6)),ISNUMBER(SEARCH("OPTICA",Inventario!B6))),"OP", IF(ISNUMBER(SEARCH("NANO",Inventario!B6)),"NA", IF(ISNUMBER(SEARCH("5050",Inventario!B6)),"5050", IF(ISNUMBER(SEARCH("MICRO",Inventario!B6)),"MI","")))))) | C7: =IF(ISNUMBER(SEARCH("PARED",Inventario!B6)),"PAR",IF(ISNUMBER(SEARCH("MATE",Inventario!B6)),"MAT", IF(ISNUMBER(SEARCH("FRONT",Inventario!B6)),"FRO", IF(ISNUMBER(SEARCH("BACK",Inventario!B6)),"BAC", IF(ISNUMBER(SEARCH("MESH",Inventario!B6)),"MES", IF(OR(ISNUMBER(SEARCH("BRILLANTE",Inventario!B6)),ISNUMBER(SEARCH("BTE",Inventario!B6))),"BRI", IF(ISNUMBER(SEARCH("SINTETICA DELGADA",Inventario!B6)),"SD", IF(ISNUMBER(SEARCH("SINTETICA GRUESA",Inventario!B6)),"SG", IF(ISNUMBER(SEARCH("ESTATICO",Inventario!B6)),"EST", IF(ISNUMBER(SEARCH("FLOOR",Inventario!B6)),"FLO", IF(ISNUMBER(SEARCH("REFLECTIVO",Inventario!B6)),"REF", IF(ISNUMBER(SEARCH("MICROPERFORADO",Inventario!B6)),"MI", IF(ISNUMBER(SEARCH("CEPILLADO",Inventario!B6)),"CEP", IF(ISNUMBER(SEARCH("ESPEJO",Inventario!B6)),"ESP", IF(OR(ISNUMBER(SEARCH("UNIDIODO",Inventario!B6)),ISNUMBER(SEARCH("1 DIODO",Inventario!B6))),"1D", IF(ISNUMBER(SEARCH("2 DIODOS",Inventario!B6)),"2D", IF(ISNUMBER(SEARCH("3 DIODOS",Inventario!B6)),"3D",""))))))))))))))))) -> FRO | D7: =IF(ISNUMBER(SEARCH("LX700",Inventario!B6)),"LX7", IF(ISNUMBER(SEARCH("GRANDO",Inventario!B6)),"GRA", IF(OR(ISNUMBER(SEARCH("CAMA PLANA",Inventario!B6)),ISNUMBER(SEARCH("FB700",Inventario!B6))),"CP", IF(ISNUMBER(SEARCH("LX360",Inventario!B6)),"LX3", IF(ISNUMBER(SEARCH("XEROX",Inventario!B6)),"XER", IF(ISNUMBER(SEARCH("18 OZ",Inventario!B6)),"18OZ", IF(ISNUMBER(SEARCH("15 OZ",Inventario!B6)),"15OZ", IF(OR(ISNUMBER(SEARCH("13 OZ",Inventario!B6)),ISNUMBER(SEARCH("13 ONZAS",Inventario!B6))),"13OZ", IF(OR(ISNUMBER(SEARCH("9 OZ",Inventario!B6)),ISNUMBER(SEARCH("9 ONZAS",Inventario!B6))),"09OZ",""))))))))) -> 13OZ | E7: =IF(OR(ISNUMBER(SEARCH("TRANSPARENTE",Inventario!B6)),ISNUMBER(SEARCH("TRANSPARENTES",Inventario!B6))),"TR", IF(OR(ISNUMBER(SEARCH("BLANCO",Inventario!B6)),ISNUMBER(SEARCH("BCO",Inventario!B6))),"BL", IF(ISNUMBER(SEARCH("VERDE",Inventario!B6)),"VR", IF(ISNUMBER(SEARCH("MORADO",Inventario!B6)),"MR", IF(ISNUMBER(SEARCH("PLATA",Inventario!B6)),"PL", IF(ISNUMBER(SEARCH("ORO",Inventario!B6)),"OR", IF(ISNUMBER(SEARCH("AMARILLO",Inventario!B6)),"AM", IF(ISNUMBER(SEARCH("NARANJA",Inventario!B6)),"NR", IF(ISNUMBER(SEARCH("NEGRO",Inventario!B6)),"NG", IF(ISNUMBER(SEARCH("ROJO",Inventario!B6)),"RJ", IF(ISNUMBER(SEARCH("AZUL",Inventario!B6)),"AZ",""))))))))))) | F7: =IF(ISNUMBER(SEARCH("1,2 MM",Inventario!B6)),"1MM2", IF(OR(ISNUMBER(SEARCH("2 MM",Inventario!B6)),ISNUMBER(SEARCH("2MM",Inventario!B6))),"2MM", IF(OR(ISNUMBER(SEARCH("3 MM",Inventario!B6)),ISNUMBER(SEARCH("3MM",Inventario!B6))),"3MM", IF(OR(ISNUMBER(SEARCH("4 MM",Inventario!B6)),ISNUMBER(SEARCH("4MM",Inventario!B6)),ISNUMBER(SEARCH("4 mm",Inventario!B6))),"4MM", IF(OR(ISNUMBER(SEARCH("5 MM",Inventario!B6)),ISNUMBER(SEARCH("5MM",Inventario!B6))),"5MM", IF(OR(ISNUMBER(SEARCH("6 MM",Inventario!B6)),ISNUMBER(SEARCH("6MM",Inventario!B6))),"6MM", IF(OR(ISNUMBER(SEARCH("10 MM",Inventario!B6)),ISNUMBER(SEARCH("10MM",Inventario!B6))),"10MM",""))))))) | G7: =IF(ISNUMBER(SEARCH("ALTA RESISTENCIA",Inventario!B6)),"AR",IF(ISNUMBER(SEARCH("CAMPAÑA",Inventario!B6)),"CA", IF(OR(ISNUMBER(SEARCH("CALIDO",Inventario!B6)),ISNUMBER(SEARCH("CÁLIDO",Inventario!B6))),"C", IF(OR(ISNUMBER(SEARCH("TRASLUCIDO",Inventario!B6)),ISNUMBER(SEARCH("TRANSLUCIDO",Inventario!B6))),"TL", IF(ISNUMBER(SEARCH("NEUTRO",Inventario!B6)),"N", IF(ISNUMBER(SEARCH("FRIO",Inventario!B6)),"F","")))))) -> AR | H7: =IF(ISNUMBER(SEARCH("SILED",Inventario!B6)),"SI", IF(ISNUMBER(SEARCH("SYDEMEX",Inventario!B6)),"SY", IF(ISNUMBER(SEARCH("ROHS",Inventario!B6)),"RO", IF(ISNUMBER(SEARCH("RISHANG",Inventario!B6)),"RS", IF(ISNUMBER(SEARCH("VYG",Inventario!B6)),"VYG", IF(ISNUMBER(SEARCH("COLED",Inventario!B6)),"CO",""))))))
A8: =IF(ISNUMBER(SEARCH("LONA",Inventario!B7)),"LON", IF(ISNUMBER(SEARCH("VINIL",Inventario!B7)),"VIN", IF(ISNUMBER(SEARCH("PANEL DE ALUMINIO COMPUESTO",Inventario!B7)),"PAN-ALU-COM", IF(ISNUMBER(SEARCH("PVC",Inventario!B7)),"PVC", IF(ISNUMBER(SEARCH("PAPEL",Inventario!B7)),"PAP", IF(ISNUMBER(SEARCH("TELA",Inventario!B7)),"TEL", IF(ISNUMBER(SEARCH("CARTULINA",Inventario!B7)),"CAR", IF(OR(ISNUMBER(SEARCH("LAMINA",Inventario!B7)),ISNUMBER(SEARCH("LÁMINA",Inventario!B7))),"LAM", IF(ISNUMBER(SEARCH("ESTIRENO",Inventario!B7)),"EST", IF(ISNUMBER(SEARCH("FOAMBOARD",Inventario!B7)),"FOA", IF(ISNUMBER(SEARCH("SOLVENTE",Inventario!B7)),"SOL", IF(ISNUMBER(SEARCH("TINTA",Inventario!B7)),"TIN", IF(ISNUMBER(SEARCH("ACRILICO",Inventario!B7)),"ACR", IF(ISNUMBER(SEARCH("LED",Inventario!B7)),"LED", IF(ISNUMBER(SEARCH("FUENTE",Inventario!B7)),"FUE", IF(ISNUMBER(SEARCH("PETG",Inventario!B7)),"PET", IF(ISNUMBER(SEARCH("ALUMINIO",Inventario!B7)),"ALU", IF(ISNUMBER(SEARCH("CANAL",Inventario!B7)),"CAN", IF(ISNUMBER(SEARCH("ESCUADRA",Inventario!B7)),"ESC", IF(ISNUMBER(SEARCH("SOPORTE",Inventario!B7)),"SOP","OTR") ))))))))))))))))))) -> LON | B8: =IF(ISNUMBER(SEARCH("CORTE",Inventario!B7)),"COR", IF(ISNUMBER(SEARCH("CRISTAL",Inventario!B7)),"CR", IF(OR(ISNUMBER(SEARCH("OPTICO",Inventario!B7)),ISNUMBER(SEARCH("OPTICOS",Inventario!B7)),ISNUMBER(SEARCH("OPTICA",Inventario!B7))),"OP", IF(ISNUMBER(SEARCH("NANO",Inventario!B7)),"NA", IF(ISNUMBER(SEARCH("5050",Inventario!B7)),"5050", IF(ISNUMBER(SEARCH("MICRO",Inventario!B7)),"MI","")))))) | C8: =IF(ISNUMBER(SEARCH("PARED",Inventario!B7)),"PAR",IF(ISNUMBER(SEARCH("MATE",Inventario!B7)),"MAT", IF(ISNUMBER(SEARCH("FRONT",Inventario!B7)),"FRO", IF(ISNUMBER(SEARCH("BACK",Inventario!B7)),"BAC", IF(ISNUMBER(SEARCH("MESH",Inventario!B7)),"MES", IF(OR(ISNUMBER(SEARCH("BRILLANTE",Inventario!B7)),ISNUMBER(SEARCH("BTE",Inventario!B7))),"BRI", IF(ISNUMBER(SEARCH("SINTETICA DELGADA",Inventario!B7)),"SD", IF(ISNUMBER(SEARCH("SINTETICA GRUESA",Inventario!B7)),"SG", IF(ISNUMBER(SEARCH("ESTATICO",Inventario!B7)),"EST", IF(ISNUMBER(SEARCH("FLOOR",Inventario!B7)),"FLO", IF(ISNUMBER(SEARCH("REFLECTIVO",Inventario!B7)),"REF", IF(ISNUMBER(SEARCH("MICROPERFORADO",Inventario!B7)),"MI", IF(ISNUMBER(SEARCH("CEPILLADO",Inventario!B7)),"CEP", IF(ISNUMBER(SEARCH("ESPEJO",Inventario!B7)),"ESP", IF(OR(ISNUMBER(SEARCH("UNIDIODO",Inventario!B7)),ISNUMBER(SEARCH("1 DIODO",Inventario!B7))),"1D", IF(ISNUMBER(SEARCH("2 DIODOS",Inventario!B7)),"2D", IF(ISNUMBER(SEARCH("3 DIODOS",Inventario!B7)),"3D",""))))))))))))))))) -> FRO | D8: =IF(ISNUMBER(SEARCH("LX700",Inventario!B7)),"LX7", IF(ISNUMBER(SEARCH("GRANDO",Inventario!B7)),"GRA", IF(OR(ISNUMBER(SEARCH("CAMA PLANA",Inventario!B7)),ISNUMBER(SEARCH("FB700",Inventario!B7))),"CP", IF(ISNUMBER(SEARCH("LX360",Inventario!B7)),"LX3", IF(ISNUMBER(SEARCH("XEROX",Inventario!B7)),"XER", IF(ISNUMBER(SEARCH("18 OZ",Inventario!B7)),"18OZ", IF(ISNUMBER(SEARCH("15 OZ",Inventario!B7)),"15OZ", IF(OR(ISNUMBER(SEARCH("13 OZ",Inventario!B7)),ISNUMBER(SEARCH("13 ONZAS",Inventario!B7))),"13OZ", IF(OR(ISNUMBER(SEARCH("9 OZ",Inventario!B7)),ISNUMBER(SEARCH("9 ONZAS",Inventario!B7))),"09OZ",""))))))))) -> 09OZ | E8: =IF(OR(ISNUMBER(SEARCH("TRANSPARENTE",Inventario!B7)),ISNUMBER(SEARCH("TRANSPARENTES",Inventario!B7))),"TR", IF(OR(ISNUMBER(SEARCH("BLANCO",Inventario!B7)),ISNUMBER(SEARCH("BCO",Inventario!B7))),"BL", IF(ISNUMBER(SEARCH("VERDE",Inventario!B7)),"VR", IF(ISNUMBER(SEARCH("MORADO",Inventario!B7)),"MR", IF(ISNUMBER(SEARCH("PLATA",Inventario!B7)),"PL", IF(ISNUMBER(SEARCH("ORO",Inventario!B7)),"OR", IF(ISNUMBER(SEARCH("AMARILLO",Inventario!B7)),"AM", IF(ISNUMBER(SEARCH("NARANJA",Inventario!B7)),"NR", IF(ISNUMBER(SEARCH("NEGRO",Inventario!B7)),"NG", IF(ISNUMBER(SEARCH("ROJO",Inventario!B7)),"RJ", IF(ISNUMBER(SEARCH("AZUL",Inventario!B7)),"AZ",""))))))))))) | F8: =IF(ISNUMBER(SEARCH("1,2 MM",Inventario!B7)),"1MM2", IF(OR(ISNUMBER(SEARCH("2 MM",Inventario!B7)),ISNUMBER(SEARCH("2MM",Inventario!B7))),"2MM", IF(OR(ISNUMBER(SEARCH("3 MM",Inventario!B7)),ISNUMBER(SEARCH("3MM",Inventario!B7))),"3MM", IF(OR(ISNUMBER(SEARCH("4 MM",Inventario!B7)),ISNUMBER(SEARCH("4MM",Inventario!B7)),ISNUMBER(SEARCH("4 mm",Inventario!B7))),"4MM", IF(OR(ISNUMBER(SEARCH("5 MM",Inventario!B7)),ISNUMBER(SEARCH("5MM",Inventario!B7))),"5MM", IF(OR(ISNUMBER(SEARCH("6 MM",Inventario!B7)),ISNUMBER(SEARCH("6MM",Inventario!B7))),"6MM", IF(OR(ISNUMBER(SEARCH("10 MM",Inventario!B7)),ISNUMBER(SEARCH("10MM",Inventario!B7))),"10MM",""))))))) | G8: =IF(ISNUMBER(SEARCH("ALTA RESISTENCIA",Inventario!B7)),"AR",IF(ISNUMBER(SEARCH("CAMPAÑA",Inventario!B7)),"CA", IF(OR(ISNUMBER(SEARCH("CALIDO",Inventario!B7)),ISNUMBER(SEARCH("CÁLIDO",Inventario!B7))),"C", IF(OR(ISNUMBER(SEARCH("TRASLUCIDO",Inventario!B7)),ISNUMBER(SEARCH("TRANSLUCIDO",Inventario!B7))),"TL", IF(ISNUMBER(SEARCH("NEUTRO",Inventario!B7)),"N", IF(ISNUMBER(SEARCH("FRIO",Inventario!B7)),"F","")))))) -> CA | H8: =IF(ISNUMBER(SEARCH("SILED",Inventario!B7)),"SI", IF(ISNUMBER(SEARCH("SYDEMEX",Inventario!B7)),"SY", IF(ISNUMBER(SEARCH("ROHS",Inventario!B7)),"RO", IF(ISNUMBER(SEARCH("RISHANG",Inventario!B7)),"RS", IF(ISNUMBER(SEARCH("VYG",Inventario!B7)),"VYG", IF(ISNUMBER(SEARCH("COLED",Inventario!B7)),"CO",""))))))
A9: =IF(ISNUMBER(SEARCH("LONA",Inventario!B8)),"LON", IF(ISNUMBER(SEARCH("VINIL",Inventario!B8)),"VIN", IF(ISNUMBER(SEARCH("PANEL DE ALUMINIO COMPUESTO",Inventario!B8)),"PAN-ALU-COM", IF(ISNUMBER(SEARCH("PVC",Inventario!B8)),"PVC", IF(ISNUMBER(SEARCH("PAPEL",Inventario!B8)),"PAP", IF(ISNUMBER(SEARCH("TELA",Inventario!B8)),"TEL", IF(ISNUMBER(SEARCH("CARTULINA",Inventario!B8)),"CAR", IF(OR(ISNUMBER(SEARCH("LAMINA",Inventario!B8)),ISNUMBER(SEARCH("LÁMINA",Inventario!B8))),"LAM", IF(ISNUMBER(SEARCH("ESTIRENO",Inventario!B8)),"EST", IF(ISNUMBER(SEARCH("FOAMBOARD",Inventario!B8)),"FOA", IF(ISNUMBER(SEARCH("SOLVENTE",Inventario!B8)),"SOL", IF(ISNUMBER(SEARCH("TINTA",Inventario!B8)),"TIN", IF(ISNUMBER(SEARCH("ACRILICO",Inventario!B8)),"ACR", IF(ISNUMBER(SEARCH("LED",Inventario!B8)),"LED", IF(ISNUMBER(SEARCH("FUENTE",Inventario!B8)),"FUE", IF(ISNUMBER(SEARCH("PETG",Inventario!B8)),"PET", IF(ISNUMBER(SEARCH("ALUMINIO",Inventario!B8)),"ALU", IF(ISNUMBER(SEARCH("CANAL",Inventario!B8)),"CAN", IF(ISNUMBER(SEARCH("ESCUADRA",Inventario!B8)),"ESC", IF(ISNUMBER(SEARCH("SOPORTE",Inventario!B8)),"SOP","OTR") ))))))))))))))))))) -> LON | B9: =IF(ISNUMBER(SEARCH("CORTE",Inventario!B8)),"COR", IF(ISNUMBER(SEARCH("CRISTAL",Inventario!B8)),"CR", IF(OR(ISNUMBER(SEARCH("OPTICO",Inventario!B8)),ISNUMBER(SEARCH("OPTICOS",Inventario!B8)),ISNUMBER(SEARCH("OPTICA",Inventario!B8))),"OP", IF(ISNUMBER(SEARCH("NANO",Inventario!B8)),"NA", IF(ISNUMBER(SEARCH("5050",Inventario!B8)),"5050", IF(ISNUMBER(SEARCH("MICRO",Inventario!B8)),"MI","")))))) | C9: =IF(ISNUMBER(SEARCH("PARED",Inventario!B8)),"PAR",IF(ISNUMBER(SEARCH("MATE",Inventario!B8)),"MAT", IF(ISNUMBER(SEARCH("FRONT",Inventario!B8)),"FRO", IF(ISNUMBER(SEARCH("BACK",Inventario!B8)),"BAC", IF(ISNUMBER(SEARCH("MESH",Inventario!B8)),"MES", IF(OR(ISNUMBER(SEARCH("BRILLANTE",Inventario!B8)),ISNUMBER(SEARCH("BTE",Inventario!B8))),"BRI", IF(ISNUMBER(SEARCH("SINTETICA DELGADA",Inventario!B8)),"SD", IF(ISNUMBER(SEARCH("SINTETICA GRUESA",Inventario!B8)),"SG", IF(ISNUMBER(SEARCH("ESTATICO",Inventario!B8)),"EST", IF(ISNUMBER(SEARCH("FLOOR",Inventario!B8)),"FLO", IF(ISNUMBER(SEARCH("REFLECTIVO",Inventario!B8)),"REF", IF(ISNUMBER(SEARCH("MICROPERFORADO",Inventario!B8)),"MI", IF(ISNUMBER(SEARCH("CEPILLADO",Inventario!B8)),"CEP", IF(ISNUMBER(SEARCH("ESPEJO",Inventario!B8)),"ESP", IF(OR(ISNUMBER(SEARCH("UNIDIODO",Inventario!B8)),ISNUMBER(SEARCH("1 DIODO",Inventario!B8))),"1D", IF(ISNUMBER(SEARCH("2 DIODOS",Inventario!B8)),"2D", IF(ISNUMBER(SEARCH("3 DIODOS",Inventario!B8)),"3D",""))))))))))))))))) -> FRO | D9: =IF(ISNUMBER(SEARCH("LX700",Inventario!B8)),"LX7", IF(ISNUMBER(SEARCH("GRANDO",Inventario!B8)),"GRA", IF(OR(ISNUMBER(SEARCH("CAMA PLANA",Inventario!B8)),ISNUMBER(SEARCH("FB700",Inventario!B8))),"CP", IF(ISNUMBER(SEARCH("LX360",Inventario!B8)),"LX3", IF(ISNUMBER(SEARCH("XEROX",Inventario!B8)),"XER", IF(ISNUMBER(SEARCH("18 OZ",Inventario!B8)),"18OZ", IF(ISNUMBER(SEARCH("15 OZ",Inventario!B8)),"15OZ", IF(OR(ISNUMBER(SEARCH("13 OZ",Inventario!B8)),ISNUMBER(SEARCH("13 ONZAS",Inventario!B8))),"13OZ", IF(OR(ISNUMBER(SEARCH("9 OZ",Inventario!B8)),ISNUMBER(SEARCH("9 ONZAS",Inventario!B8))),"09OZ",""))))))))) -> 09OZ | E9: =IF(OR(ISNUMBER(SEARCH("TRANSPARENTE",Inventario!B8)),ISNUMBER(SEARCH("TRANSPARENTES",Inventario!B8))),"TR", IF(OR(ISNUMBER(SEARCH("BLANCO",Inventario!B8)),ISNUMBER(SEARCH("BCO",Inventario!B8))),"BL", IF(ISNUMBER(SEARCH("VERDE",Inventario!B8)),"VR", IF(ISNUMBER(SEARCH("MORADO",Inventario!B8)),"MR", IF(ISNUMBER(SEARCH("PLATA",Inventario!B8)),"PL", IF(ISNUMBER(SEARCH("ORO",Inventario!B8)),"OR", IF(ISNUMBER(SEARCH("AMARILLO",Inventario!B8)),"AM", IF(ISNUMBER(SEARCH("NARANJA",Inventario!B8)),"NR", IF(ISNUMBER(SEARCH("NEGRO",Inventario!B8)),"NG", IF(ISNUMBER(SEARCH("ROJO",Inventario!B8)),"RJ", IF(ISNUMBER(SEARCH("AZUL",Inventario!B8)),"AZ",""))))))))))) | F9: =IF(ISNUMBER(SEARCH("1,2 MM",Inventario!B8)),"1MM2", IF(OR(ISNUMBER(SEARCH("2 MM",Inventario!B8)),ISNUMBER(SEARCH("2MM",Inventario!B8))),"2MM", IF(OR(ISNUMBER(SEARCH("3 MM",Inventario!B8)),ISNUMBER(SEARCH("3MM",Inventario!B8))),"3MM", IF(OR(ISNUMBER(SEARCH("4 MM",Inventario!B8)),ISNUMBER(SEARCH("4MM",Inventario!B8)),ISNUMBER(SEARCH("4 mm",Inventario!B8))),"4MM", IF(OR(ISNUMBER(SEARCH("5 MM",Inventario!B8)),ISNUMBER(SEARCH("5MM",Inventario!B8))),"5MM", IF(OR(ISNUMBER(SEARCH("6 MM",Inventario!B8)),ISNUMBER(SEARCH("6MM",Inventario!B8))),"6MM", IF(OR(ISNUMBER(SEARCH("10 MM",Inventario!B8)),ISNUMBER(SEARCH("10MM",Inventario!B8))),"10MM",""))))))) | G9: =IF(ISNUMBER(SEARCH("ALTA RESISTENCIA",Inventario!B8)),"AR",IF(ISNUMBER(SEARCH("CAMPAÑA",Inventario!B8)),"CA", IF(OR(ISNUMBER(SEARCH("CALIDO",Inventario!B8)),ISNUMBER(SEARCH("CÁLIDO",Inventario!B8))),"C", IF(OR(ISNUMBER(SEARCH("TRASLUCIDO",Inventario!B8)),ISNUMBER(SEARCH("TRANSLUCIDO",Inventario!B8))),"TL", IF(ISNUMBER(SEARCH("NEUTRO",Inventario!B8)),"N", IF(ISNUMBER(SEARCH("FRIO",Inventario!B8)),"F","")))))) -> CA | H9: =IF(ISNUMBER(SEARCH("SILED",Inventario!B8)),"SI", IF(ISNUMBER(SEARCH("SYDEMEX",Inventario!B8)),"SY", IF(ISNUMBER(SEARCH("ROHS",Inventario!B8)),"RO", IF(ISNUMBER(SEARCH("RISHANG",Inventario!B8)),"RS", IF(ISNUMBER(SEARCH("VYG",Inventario!B8)),"VYG", IF(ISNUMBER(SEARCH("COLED",Inventario!B8)),"CO",""))))))
A10: =IF(ISNUMBER(SEARCH("LONA",Inventario!B9)),"LON", IF(ISNUMBER(SEARCH("VINIL",Inventario!B9)),"VIN", IF(ISNUMBER(SEARCH("PANEL DE ALUMINIO COMPUESTO",Inventario!B9)),"PAN-ALU-COM", IF(ISNUMBER(SEARCH("PVC",Inventario!B9)),"PVC", IF(ISNUMBER(SEARCH("PAPEL",Inventario!B9)),"PAP", IF(ISNUMBER(SEARCH("TELA",Inventario!B9)),"TEL", IF(ISNUMBER(SEARCH("CARTULINA",Inventario!B9)),"CAR", IF(OR(ISNUMBER(SEARCH("LAMINA",Inventario!B9)),ISNUMBER(SEARCH("LÁMINA",Inventario!B9))),"LAM", IF(ISNUMBER(SEARCH("ESTIRENO",Inventario!B9)),"EST", IF(ISNUMBER(SEARCH("FOAMBOARD",Inventario!B9)),"FOA", IF(ISNUMBER(SEARCH("SOLVENTE",Inventario!B9)),"SOL", IF(ISNUMBER(SEARCH("TINTA",Inventario!B9)),"TIN", IF(ISNUMBER(SEARCH("ACRILICO",Inventario!B9)),"ACR", IF(ISNUMBER(SEARCH("LED",Inventario!B9)),"LED", IF(ISNUMBER(SEARCH("FUENTE",Inventario!B9)),"FUE", IF(ISNUMBER(SEARCH("PETG",Inventario!B9)),"PET", IF(ISNUMBER(SEARCH("ALUMINIO",Inventario!B9)),"ALU", IF(ISNUMBER(SEARCH("CANAL",Inventario!B9)),"CAN", IF(ISNUMBER(SEARCH("ESCUADRA",Inventario!B9)),"ESC", IF(ISNUMBER(SEARCH("SOPORTE",Inventario!B9)),"SOP","OTR") ))))))))))))))))))) -> LON | B10: =IF(ISNUMBER(SEARCH("CORTE",Inventario!B9)),"COR", IF(ISNUMBER(SEARCH("CRISTAL",Inventario!B9)),"CR", IF(OR(ISNUMBER(SEARCH("OPTICO",Inventario!B9)),ISNUMBER(SEARCH("OPTICOS",Inventario!B9)),ISNUMBER(SEARCH("OPTICA",Inventario!B9))),"OP", IF(ISNUMBER(SEARCH("NANO",Inventario!B9)),"NA", IF(ISNUMBER(SEARCH("5050",Inventario!B9)),"5050", IF(ISNUMBER(SEARCH("MICRO",Inventario!B9)),"MI","")))))) | C10: =IF(ISNUMBER(SEARCH("PARED",Inventario!B9)),"PAR",IF(ISNUMBER(SEARCH("MATE",Inventario!B9)),"MAT", IF(ISNUMBER(SEARCH("FRONT",Inventario!B9)),"FRO", IF(ISNUMBER(SEARCH("BACK",Inventario!B9)),"BAC", IF(ISNUMBER(SEARCH("MESH",Inventario!B9)),"MES", IF(OR(ISNUMBER(SEARCH("BRILLANTE",Inventario!B9)),ISNUMBER(SEARCH("BTE",Inventario!B9))),"BRI", IF(ISNUMBER(SEARCH("SINTETICA DELGADA",Inventario!B9)),"SD", IF(ISNUMBER(SEARCH("SINTETICA GRUESA",Inventario!B9)),"SG", IF(ISNUMBER(SEARCH("ESTATICO",Inventario!B9)),"EST", IF(ISNUMBER(SEARCH("FLOOR",Inventario!B9)),"FLO", IF(ISNUMBER(SEARCH("REFLECTIVO",Inventario!B9)),"REF", IF(ISNUMBER(SEARCH("MICROPERFORADO",Inventario!B9)),"MI", IF(ISNUMBER(SEARCH("CEPILLADO",Inventario!B9)),"CEP", IF(ISNUMBER(SEARCH("ESPEJO",Inventario!B9)),"ESP", IF(OR(ISNUMBER(SEARCH("UNIDIODO",Inventario!B9)),ISNUMBER(SEARCH("1 DIODO",Inventario!B9))),"1D", IF(ISNUMBER(SEARCH("2 DIODOS",Inventario!B9)),"2D", IF(ISNUMBER(SEARCH("3 DIODOS",Inventario!B9)),"3D",""))))))))))))))))) -> FRO | D10: =IF(ISNUMBER(SEARCH("LX700",Inventario!B9)),"LX7", IF(ISNUMBER(SEARCH("GRANDO",Inventario!B9)),"GRA", IF(OR(ISNUMBER(SEARCH("CAMA PLANA",Inventario!B9)),ISNUMBER(SEARCH("FB700",Inventario!B9))),"CP", IF(ISNUMBER(SEARCH("LX360",Inventario!B9)),"LX3", IF(ISNUMBER(SEARCH("XEROX",Inventario!B9)),"XER", IF(ISNUMBER(SEARCH("18 OZ",Inventario!B9)),"18OZ", IF(ISNUMBER(SEARCH("15 OZ",Inventario!B9)),"15OZ", IF(OR(ISNUMBER(SEARCH("13 OZ",Inventario!B9)),ISNUMBER(SEARCH("13 ONZAS",Inventario!B9))),"13OZ", IF(OR(ISNUMBER(SEARCH("9 OZ",Inventario!B9)),ISNUMBER(SEARCH("9 ONZAS",Inventario!B9))),"09OZ",""))))))))) -> 13OZ | E10: =IF(OR(ISNUMBER(SEARCH("TRANSPARENTE",Inventario!B9)),ISNUMBER(SEARCH("TRANSPARENTES",Inventario!B9))),"TR", IF(OR(ISNUMBER(SEARCH("BLANCO",Inventario!B9)),ISNUMBER(SEARCH("BCO",Inventario!B9))),"BL", IF(ISNUMBER(SEARCH("VERDE",Inventario!B9)),"VR", IF(ISNUMBER(SEARCH("MORADO",Inventario!B9)),"MR", IF(ISNUMBER(SEARCH("PLATA",Inventario!B9)),"PL", IF(ISNUMBER(SEARCH("ORO",Inventario!B9)),"OR", IF(ISNUMBER(SEARCH("AMARILLO",Inventario!B9)),"AM", IF(ISNUMBER(SEARCH("NARANJA",Inventario!B9)),"NR", IF(ISNUMBER(SEARCH("NEGRO",Inventario!B9)),"NG", IF(ISNUMBER(SEARCH("ROJO",Inventario!B9)),"RJ", IF(ISNUMBER(SEARCH("AZUL",Inventario!B9)),"AZ",""))))))))))) | F10: =IF(ISNUMBER(SEARCH("1,2 MM",Inventario!B9)),"1MM2", IF(OR(ISNUMBER(SEARCH("2 MM",Inventario!B9)),ISNUMBER(SEARCH("2MM",Inventario!B9))),"2MM", IF(OR(ISNUMBER(SEARCH("3 MM",Inventario!B9)),ISNUMBER(SEARCH("3MM",Inventario!B9))),"3MM", IF(OR(ISNUMBER(SEARCH("4 MM",Inventario!B9)),ISNUMBER(SEARCH("4MM",Inventario!B9)),ISNUMBER(SEARCH("4 mm",Inventario!B9))),"4MM", IF(OR(ISNUMBER(SEARCH("5 MM",Inventario!B9)),ISNUMBER(SEARCH("5MM",Inventario!B9))),"5MM", IF(OR(ISNUMBER(SEARCH("6 MM",Inventario!B9)),ISNUMBER(SEARCH("6MM",Inventario!B9))),"6MM", IF(OR(ISNUMBER(SEARCH("10 MM",Inventario!B9)),ISNUMBER(SEARCH("10MM",Inventario!B9))),"10MM",""))))))) | G10: =IF(ISNUMBER(SEARCH("ALTA RESISTENCIA",Inventario!B9)),"AR",IF(ISNUMBER(SEARCH("CAMPAÑA",Inventario!B9)),"CA", IF(OR(ISNUMBER(SEARCH("CALIDO",Inventario!B9)),ISNUMBER(SEARCH("CÁLIDO",Inventario!B9))),"C", IF(OR(ISNUMBER(SEARCH("TRASLUCIDO",Inventario!B9)),ISNUMBER(SEARCH("TRANSLUCIDO",Inventario!B9))),"TL", IF(ISNUMBER(SEARCH("NEUTRO",Inventario!B9)),"N", IF(ISNUMBER(SEARCH("FRIO",Inventario!B9)),"F","")))))) -> AR | H10: =IF(ISNUMBER(SEARCH("SILED",Inventario!B9)),"SI", IF(ISNUMBER(SEARCH("SYDEMEX",Inventario!B9)),"SY", IF(ISNUMBER(SEARCH("ROHS",Inventario!B9)),"RO", IF(ISNUMBER(SEARCH("RISHANG",Inventario!B9)),"RS", IF(ISNUMBER(SEARCH("VYG",Inventario!B9)),"VYG", IF(ISNUMBER(SEARCH("COLED",Inventario!B9)),"CO",""))))))
A11: =IF(ISNUMBER(SEARCH("LONA",Inventario!B10)),"LON", IF(ISNUMBER(SEARCH("VINIL",Inventario!B10)),"VIN", IF(ISNUMBER(SEARCH("PANEL DE ALUMINIO COMPUESTO",Inventario!B10)),"PAN-ALU-COM", IF(ISNUMBER(SEARCH("PVC",Inventario!B10)),"PVC", IF(ISNUMBER(SEARCH("PAPEL",Inventario!B10)),"PAP", IF(ISNUMBER(SEARCH("TELA",Inventario!B10)),"TEL", IF(ISNUMBER(SEARCH("CARTULINA",Inventario!B10)),"CAR", IF(OR(ISNUMBER(SEARCH("LAMINA",Inventario!B10)),ISNUMBER(SEARCH("LÁMINA",Inventario!B10))),"LAM", IF(ISNUMBER(SEARCH("ESTIRENO",Inventario!B10)),"EST", IF(ISNUMBER(SEARCH("FOAMBOARD",Inventario!B10)),"FOA", IF(ISNUMBER(SEARCH("SOLVENTE",Inventario!B10)),"SOL", IF(ISNUMBER(SEARCH("TINTA",Inventario!B10)),"TIN", IF(ISNUMBER(SEARCH("ACRILICO",Inventario!B10)),"ACR", IF(ISNUMBER(SEARCH("LED",Inventario!B10)),"LED", IF(ISNUMBER(SEARCH("FUENTE",Inventario!B10)),"FUE", IF(ISNUMBER(SEARCH("PETG",Inventario!B10)),"PET", IF(ISNUMBER(SEARCH("ALUMINIO",Inventario!B10)),"ALU", IF(ISNUMBER(SEARCH("CANAL",Inventario!B10)),"CAN", IF(ISNUMBER(SEARCH("ESCUADRA",Inventario!B10)),"ESC", IF(ISNUMBER(SEARCH("SOPORTE",Inventario!B10)),"SOP","OTR") ))))))))))))))))))) -> LON | B11: =IF(ISNUMBER(SEARCH("CORTE",Inventario!B10)),"COR", IF(ISNUMBER(SEARCH("CRISTAL",Inventario!B10)),"CR", IF(OR(ISNUMBER(SEARCH("OPTICO",Inventario!B10)),ISNUMBER(SEARCH("OPTICOS",Inventario!B10)),ISNUMBER(SEARCH("OPTICA",Inventario!B10))),"OP", IF(ISNUMBER(SEARCH("NANO",Inventario!B10)),"NA", IF(ISNUMBER(SEARCH("5050",Inventario!B10)),"5050", IF(ISNUMBER(SEARCH("MICRO",Inventario!B10)),"MI","")))))) | C11: =IF(ISNUMBER(SEARCH("PARED",Inventario!B10)),"PAR",IF(ISNUMBER(SEARCH("MATE",Inventario!B10)),"MAT", IF(ISNUMBER(SEARCH("FRONT",Inventario!B10)),"FRO", IF(ISNUMBER(SEARCH("BACK",Inventario!B10)),"BAC", IF(ISNUMBER(SEARCH("MESH",Inventario!B10)),"MES", IF(OR(ISNUMBER(SEARCH("BRILLANTE",Inventario!B10)),ISNUMBER(SEARCH("BTE",Inventario!B10))),"BRI", IF(ISNUMBER(SEARCH("SINTETICA DELGADA",Inventario!B10)),"SD", IF(ISNUMBER(SEARCH("SINTETICA GRUESA",Inventario!B10)),"SG", IF(ISNUMBER(SEARCH("ESTATICO",Inventario!B10)),"EST", IF(ISNUMBER(SEARCH("FLOOR",Inventario!B10)),"FLO", IF(ISNUMBER(SEARCH("REFLECTIVO",Inventario!B10)),"REF", IF(ISNUMBER(SEARCH("MICROPERFORADO",Inventario!B10)),"MI", IF(ISNUMBER(SEARCH("CEPILLADO",Inventario!B10)),"CEP", IF(ISNUMBER(SEARCH("ESPEJO",Inventario!B10)),"ESP", IF(OR(ISNUMBER(SEARCH("UNIDIODO",Inventario!B10)),ISNUMBER(SEARCH("1 DIODO",Inventario!B10))),"1D", IF(ISNUMBER(SEARCH("2 DIODOS",Inventario!B10)),"2D", IF(ISNUMBER(SEARCH("3 DIODOS",Inventario!B10)),"3D",""))))))))))))))))) -> FRO | D11: =IF(ISNUMBER(SEARCH("LX700",Inventario!B10)),"LX7", IF(ISNUMBER(SEARCH("GRANDO",Inventario!B10)),"GRA", IF(OR(ISNUMBER(SEARCH("CAMA PLANA",Inventario!B10)),ISNUMBER(SEARCH("FB700",Inventario!B10))),"CP", IF(ISNUMBER(SEARCH("LX360",Inventario!B10)),"LX3", IF(ISNUMBER(SEARCH("XEROX",Inventario!B10)),"XER", IF(ISNUMBER(SEARCH("18 OZ",Inventario!B10)),"18OZ", IF(ISNUMBER(SEARCH("15 OZ",Inventario!B10)),"15OZ", IF(OR(ISNUMBER(SEARCH("13 OZ",Inventario!B10)),ISNUMBER(SEARCH("13 ONZAS",Inventario!B10))),"13OZ", IF(OR(ISNUMBER(SEARCH("9 OZ",Inventario!B10)),ISNUMBER(SEARCH("9 ONZAS",Inventario!B10))),"09OZ",""))))))))) -> 13OZ | E11: =IF(OR(ISNUMBER(SEARCH("TRANSPARENTE",Inventario!B10)),ISNUMBER(SEARCH("TRANSPARENTES",Inventario!B10))),"TR", IF(OR(ISNUMBER(SEARCH("BLANCO",Inventario!B10)),ISNUMBER(SEARCH("BCO",Inventario!B10))),"BL", IF(ISNUMBER(SEARCH("VERDE",Inventario!B10)),"VR", IF(ISNUMBER(SEARCH("MORADO",Inventario!B10)),"MR", IF(ISNUMBER(SEARCH("PLATA",Inventario!B10)),"PL", IF(ISNUMBER(SEARCH("ORO",Inventario!B10)),"OR", IF(ISNUMBER(SEARCH("AMARILLO",Inventario!B10)),"AM", IF(ISNUMBER(SEARCH("NARANJA",Inventario!B10)),"NR", IF(ISNUMBER(SEARCH("NEGRO",Inventario!B10)),"NG", IF(ISNUMBER(SEARCH("ROJO",Inventario!B10)),"RJ", IF(ISNUMBER(SEARCH("AZUL",Inventario!B10)),"AZ",""))))))))))) | F11: =IF(ISNUMBER(SEARCH("1,2 MM",Inventario!B10)),"1MM2", IF(OR(ISNUMBER(SEARCH("2 MM",Inventario!B10)),ISNUMBER(SEARCH("2MM",Inventario!B10))),"2MM", IF(OR(ISNUMBER(SEARCH("3 MM",Inventario!B10)),ISNUMBER(SEARCH("3MM",Inventario!B10))),"3MM", IF(OR(ISNUMBER(SEARCH("4 MM",Inventario!B10)),ISNUMBER(SEARCH("4MM",Inventario!B10)),ISNUMBER(SEARCH("4 mm",Inventario!B10))),"4MM", IF(OR(ISNUMBER(SEARCH("5 MM",Inventario!B10)),ISNUMBER(SEARCH("5MM",Inventario!B10))),"5MM", IF(OR(ISNUMBER(SEARCH("6 MM",Inventario!B10)),ISNUMBER(SEARCH("6MM",Inventario!B10))),"6MM", IF(OR(ISNUMBER(SEARCH("10 MM",Inventario!B10)),ISNUMBER(SEARCH("10MM",Inventario!B10))),"10MM",""))))))) | G11: =IF(ISNUMBER(SEARCH("ALTA RESISTENCIA",Inventario!B10)),"AR",IF(ISNUMBER(SEARCH("CAMPAÑA",Inventario!B10)),"CA", IF(OR(ISNUMBER(SEARCH("CALIDO",Inventario!B10)),ISNUMBER(SEARCH("CÁLIDO",Inventario!B10))),"C", IF(OR(ISNUMBER(SEARCH("TRASLUCIDO",Inventario!B10)),ISNUMBER(SEARCH("TRANSLUCIDO",Inventario!B10))),"TL", IF(ISNUMBER(SEARCH("NEUTRO",Inventario!B10)),"N", IF(ISNUMBER(SEARCH("FRIO",Inventario!B10)),"F","")))))) -> AR | H11: =IF(ISNUMBER(SEARCH("SILED",Inventario!B10)),"SI", IF(ISNUMBER(SEARCH("SYDEMEX",Inventario!B10)),"SY", IF(ISNUMBER(SEARCH("ROHS",Inventario!B10)),"RO", IF(ISNUMBER(SEARCH("RISHANG",Inventario!B10)),"RS", IF(ISNUMBER(SEARCH("VYG",Inventario!B10)),"VYG", IF(ISNUMBER(SEARCH("COLED",Inventario!B10)),"CO",""))))))
A12: =IF(ISNUMBER(SEARCH("LONA",Inventario!B11)),"LON", IF(ISNUMBER(SEARCH("VINIL",Inventario!B11)),"VIN", IF(ISNUMBER(SEARCH("PANEL DE ALUMINIO COMPUESTO",Inventario!B11)),"PAN-ALU-COM", IF(ISNUMBER(SEARCH("PVC",Inventario!B11)),"PVC", IF(ISNUMBER(SEARCH("PAPEL",Inventario!B11)),"PAP", IF(ISNUMBER(SEARCH("TELA",Inventario!B11)),"TEL", IF(ISNUMBER(SEARCH("CARTULINA",Inventario!B11)),"CAR", IF(OR(ISNUMBER(SEARCH("LAMINA",Inventario!B11)),ISNUMBER(SEARCH("LÁMINA",Inventario!B11))),"LAM", IF(ISNUMBER(SEARCH("ESTIRENO",Inventario!B11)),"EST", IF(ISNUMBER(SEARCH("FOAMBOARD",Inventario!B11)),"FOA", IF(ISNUMBER(SEARCH("SOLVENTE",Inventario!B11)),"SOL", IF(ISNUMBER(SEARCH("TINTA",Inventario!B11)),"TIN", IF(ISNUMBER(SEARCH("ACRILICO",Inventario!B11)),"ACR", IF(ISNUMBER(SEARCH("LED",Inventario!B11)),"LED", IF(ISNUMBER(SEARCH("FUENTE",Inventario!B11)),"FUE", IF(ISNUMBER(SEARCH("PETG",Inventario!B11)),"PET", IF(ISNUMBER(SEARCH("ALUMINIO",Inventario!B11)),"ALU", IF(ISNUMBER(SEARCH("CANAL",Inventario!B11)),"CAN", IF(ISNUMBER(SEARCH("ESCUADRA",Inventario!B11)),"ESC", IF(ISNUMBER(SEARCH("SOPORTE",Inventario!B11)),"SOP","OTR") ))))))))))))))))))) -> LON | B12: =IF(ISNUMBER(SEARCH("CORTE",Inventario!B11)),"COR", IF(ISNUMBER(SEARCH("CRISTAL",Inventario!B11)),"CR", IF(OR(ISNUMBER(SEARCH("OPTICO",Inventario!B11)),ISNUMBER(SEARCH("OPTICOS",Inventario!B11)),ISNUMBER(SEARCH("OPTICA",Inventario!B11))),"OP", IF(ISNUMBER(SEARCH("NANO",Inventario!B11)),"NA", IF(ISNUMBER(SEARCH("5050",Inventario!B11)),"5050", IF(ISNUMBER(SEARCH("MICRO",Inventario!B11)),"MI","")))))) | C12: =IF(ISNUMBER(SEARCH("PARED",Inventario!B11)),"PAR",IF(ISNUMBER(SEARCH("MATE",Inventario!B11)),"MAT", IF(ISNUMBER(SEARCH("FRONT",Inventario!B11)),"FRO", IF(ISNUMBER(SEARCH("BACK",Inventario!B11)),"BAC", IF(ISNUMBER(SEARCH("MESH",Inventario!B11)),"MES", IF(OR(ISNUMBER(SEARCH("BRILLANTE",Inventario!B11)),ISNUMBER(SEARCH("BTE",Inventario!B11))),"BRI", IF(ISNUMBER(SEARCH("SINTETICA DELGADA",Inventario!B11)),"SD", IF(ISNUMBER(SEARCH("SINTETICA GRUESA",Inventario!B11)),"SG", IF(ISNUMBER(SEARCH("ESTATICO",Inventario!B11)),"EST", IF(ISNUMBER(SEARCH("FLOOR",Inventario!B11)),"FLO", IF(ISNUMBER(SEARCH("REFLECTIVO",Inventario!B11)),"REF", IF(ISNUMBER(SEARCH("MICROPERFORADO",Inventario!B11)),"MI", IF(ISNUMBER(SEARCH("CEPILLADO",Inventario!B11)),"CEP", IF(ISNUMBER(SEARCH("ESPEJO",Inventario!B11)),"ESP", IF(OR(ISNUMBER(SEARCH("UNIDIODO",Inventario!B11)),ISNUMBER(SEARCH("1 DIODO",Inventario!B11))),"1D", IF(ISNUMBER(SEARCH("2 DIODOS",Inventario!B11)),"2D", IF(ISNUMBER(SEARCH("3 DIODOS",Inventario!B11)),"3D",""))))))))))))))))) -> FRO | D12: =IF(ISNUMBER(SEARCH("LX700",Inventario!B11)),"LX7", IF(ISNUMBER(SEARCH("GRANDO",Inventario!B11)),"GRA", IF(OR(ISNUMBER(SEARCH("CAMA PLANA",Inventario!B11)),ISNUMBER(SEARCH("FB700",Inventario!B11))),"CP", IF(ISNUMBER(SEARCH("LX360",Inventario!B11)),"LX3", IF(ISNUMBER(SEARCH("XEROX",Inventario!B11)),"XER", IF(ISNUMBER(SEARCH("18 OZ",Inventario!B11)),"18OZ", IF(ISNUMBER(SEARCH("15 OZ",Inventario!B11)),"15OZ", IF(OR(ISNUMBER(SEARCH("13 OZ",Inventario!B11)),ISNUMBER(SEARCH("13 ONZAS",Inventario!B11))),"13OZ", IF(OR(ISNUMBER(SEARCH("9 OZ",Inventario!B11)),ISNUMBER(SEARCH("9 ONZAS",Inventario!B11))),"09OZ",""))))))))) -> 13OZ | E12: =IF(OR(ISNUMBER(SEARCH("TRANSPARENTE",Inventario!B11)),ISNUMBER(SEARCH("TRANSPARENTES",Inventario!B11))),"TR", IF(OR(ISNUMBER(SEARCH("BLANCO",Inventario!B11)),ISNUMBER(SEARCH("BCO",Inventario!B11))),"BL", IF(ISNUMBER(SEARCH("VERDE",Inventario!B11)),"VR", IF(ISNUMBER(SEARCH("MORADO",Inventario!B11)),"MR", IF(ISNUMBER(SEARCH("PLATA",Inventario!B11)),"PL", IF(ISNUMBER(SEARCH("ORO",Inventario!B11)),"OR", IF(ISNUMBER(SEARCH("AMARILLO",Inventario!B11)),"AM", IF(ISNUMBER(SEARCH("NARANJA",Inventario!B11)),"NR", IF(ISNUMBER(SEARCH("NEGRO",Inventario!B11)),"NG", IF(ISNUMBER(SEARCH("ROJO",Inventario!B11)),"RJ", IF(ISNUMBER(SEARCH("AZUL",Inventario!B11)),"AZ",""))))))))))) | F12: =IF(ISNUMBER(SEARCH("1,2 MM",Inventario!B11)),"1MM2", IF(OR(ISNUMBER(SEARCH("2 MM",Inventario!B11)),ISNUMBER(SEARCH("2MM",Inventario!B11))),"2MM", IF(OR(ISNUMBER(SEARCH("3 MM",Inventario!B11)),ISNUMBER(SEARCH("3MM",Inventario!B11))),"3MM", IF(OR(ISNUMBER(SEARCH("4 MM",Inventario!B11)),ISNUMBER(SEARCH("4MM",Inventario!B11)),ISNUMBER(SEARCH("4 mm",Inventario!B11))),"4MM", IF(OR(ISNUMBER(SEARCH("5 MM",Inventario!B11)),ISNUMBER(SEARCH("5MM",Inventario!B11))),"5MM", IF(OR(ISNUMBER(SEARCH("6 MM",Inventario!B11)),ISNUMBER(SEARCH("6MM",Inventario!B11))),"6MM", IF(OR(ISNUMBER(SEARCH("10 MM",Inventario!B11)),ISNUMBER(SEARCH("10MM",Inventario!B11))),"10MM",""))))))) | G12: =IF(ISNUMBER(SEARCH("ALTA RESISTENCIA",Inventario!B11)),"AR",IF(ISNUMBER(SEARCH("CAMPAÑA",Inventario!B11)),"CA", IF(OR(ISNUMBER(SEARCH("CALIDO",Inventario!B11)),ISNUMBER(SEARCH("CÁLIDO",Inventario!B11))),"C", IF(OR(ISNUMBER(SEARCH("TRASLUCIDO",Inventario!B11)),ISNUMBER(SEARCH("TRANSLUCIDO",Inventario!B11))),"TL", IF(ISNUMBER(SEARCH("NEUTRO",Inventario!B11)),"N", IF(ISNUMBER(SEARCH("FRIO",Inventario!B11)),"F","")))))) -> AR | H12: =IF(ISNUMBER(SEARCH("SILED",Inventario!B11)),"SI", IF(ISNUMBER(SEARCH("SYDEMEX",Inventario!B11)),"SY", IF(ISNUMBER(SEARCH("ROHS",Inventario!B11)),"RO", IF(ISNUMBER(SEARCH("RISHANG",Inventario!B11)),"RS", IF(ISNUMBER(SEARCH("VYG",Inventario!B11)),"VYG", IF(ISNUMBER(SEARCH("COLED",Inventario!B11)),"CO",""))))))
