Workbook

Sheet RELACIONES
A1: skuProduct | B1: PROVEEDOR | C1: sku
A3: =INVENTARIO!A3 -> LON-BAC-1 | B3: POLYVINILOS | C3: =IFERROR(A3&"-"&_xlfn.XLOOKUP(B3,PROVEEDORES!$D$3:$D$37,PROVEEDORES!$B$3:$B$37),"") -> LON-BAC-1-Y
A4: =INVENTARIO!A4 -> LON-BAC-2 | B4: MEXTRAN | C4: =IFERROR(A4&"-"&_xlfn.XLOOKUP(B4,PROVEEDORES!$D$3:$D$37,PROVEEDORES!$B$3:$B$37),"") -> LON-BAC-2-V
A5: =INVENTARIO!A5 -> LON-BAC-3 | B5: MEXTRAN | C5: =IFERROR(A5&"-"&_xlfn.XLOOKUP(B5,PROVEEDORES!$D$3:$D$37,PROVEEDORES!$B$3:$B$37),"") -> LON-BAC-3-V
A6: =INVENTARIO!A6 -> LON-FRO-13OZ-1 | B6: POLYVINILOS | C6: =IFERROR(A6&"-"&_xlfn.XLOOKUP(B6,PROVEEDORES!$D$3:$D$37,PROVEEDORES!$B$3:$B$37),"") -> LON-FRO-13OZ-1-Y
A7: =INVENTARIO!A7 -> LON-FRO-13OZ-2 | B7: MEXTRAN | C7: =IFERROR(A7&"-"&_xlfn.XLOOKUP(B7,PROVEEDORES!$D$3:$D$37,PROVEEDORES!$B$3:$B$37),"") -> LON-FRO-13OZ-2-V
A8: =INVENTARIO!A8 -> LON-FRO-13OZ-3 | B8: MEXTRAN | C8: =IFERROR(A8&"-"&_xlfn.XLOOKUP(B8,PROVEEDORES!$D$3:$D$37,PROVEEDORES!$B$3:$B$37),"") -> LON-FRO-13OZ-3-V
A9: =INVENTARIO!A9 -> LON-FRO-13OZ-4 | B9: MEXTRAN | C9: =IFERROR(A9&"-"&_xlfn.XLOOKUP(B9,PROVEEDORES!$D$3:$D$37,PROVEEDORES!$B$3:$B$37),"") -> LON-FRO-13OZ-4-V
A10: =INVENTARIO!A10 -> LON-FRO-13OZ-5 | B10: MEXTRAN | C10: =IFERROR(A10&"-"&_xlfn.XLOOKUP(B10,PROVEEDORES!$D$3:$D$37,PROVEEDORES!$B$3:$B$37),"") -> LON-FRO-13OZ-5-V
A11: =INVENTARIO!A11 -> LON-FRO-13OZ-6 | B11: MEXTRAN | C11: =IFERROR(A11&"-"&_xlfn.XLOOKUP(B11,PROVEEDORES!$D$3:$D$37,PROVEEDORES!$B$3:$B$37),"") -> LON-FRO-13OZ-6-V
A12: =INVENTARIO!A12 -> LON-FRO-13OZ-7 | B12: MEXTRAN | C12: =IFERROR(A12&"-"&_xlfn.XLOOKUP(B12,PROVEEDORES!$D$3:$D$37,PROVEEDORES!$B$3:$B$37),"") -> LON-FRO-13OZ-7-V
A13: =INVENTARIO!A13 -> LON-ALT-RES-1 | B13: MEXTRAN | C13: =IFERROR(A13&"-"&_xlfn.XLOOKUP(B13,PROVEEDORES!$D$3:$D$37,PROVEEDORES!$B$3:$B$37),"") -> LON-ALT-RES-1-V
A14: =INVENTARIO!A14 -> LON-ALT-RES-2 | B14: MEXTRAN | C14: =IFERROR(A14&"-"&_xlfn.XLOOKUP(B14,PROVEEDORES!$D$3:$D$37,PROVEEDORES!$B$3:$B$37),"") -> LON-ALT-RES-2-V
... A344: =INVENTARIO!A344 -> FAB-350GR-1 | B344: SERVIMERC | C344: =IFERROR(A344&"-"&_xlfn.XLOOKUP(B344,PROVEEDORES!$D$3:$D$37,PROVEEDORES!$B$3:$B$37),"") -> FAB-350GR-1-AC

Sheet PRODUCTOS
A2: sku | B2: name | C2: base | D2: height | E2: currentStock | F2: minStock | G2: presentation
A3: {=_xlfn.UNIQUE(INVENTARIO!A3:A344,FALSE,TRUE)} -> LON-BAC-1 | B3: =IF(PRODUCTOS!A3="","",_xlfn.XLOOKUP(PRODUCTOS!A3,INVENTARIO!A3:A344,INVENTARIO!C3:C344)) -> LONA BACKLITE | C3: =IF(PRODUCTOS!A3="","",_xlfn.XLOOKUP(PRODUCTOS!A3,INVENTARIO!A3:A344,INVENTARIO!D3:D344)) -> 1,6 | D3: =IF(PRODUCTOS!A3="","",_xlfn.XLOOKUP(PRODUCTOS!A3,INVENTARIO!A3:A344,INVENTARIO!E3:E344)) -> 50 | G3: ROLLO
A4: LON-BAC-2 | B4: =IF(PRODUCTOS!A4="","",_xlfn.XLOOKUP(PRODUCTOS!A4,INVENTARIO!A4:A345,INVENTARIO!C4:C345)) -> LONA BACKLITE | C4: =IF(PRODUCTOS!A4="","",_xlfn.XLOOKUP(PRODUCTOS!A4,INVENTARIO!A4:A345,INVENTARIO!D4:D345)) -> 2,5 | D4: =IF(PRODUCTOS!A4="","",_xlfn.XLOOKUP(PRODUCTOS!A4,INVENTARIO!A4:A345,INVENTARIO!E4:E345)) -> 50 | G4: ROLLO
A5: LON-BAC-3 | B5: =IF(PRODUCTOS!A5="","",_xlfn.XLOOKUP(PRODUCTOS!A5,INVENTARIO!A5:A346,INVENTARIO!C5:C346)) -> LONA BACKLITE | C5: =IF(PRODUCTOS!A5="","",_xlfn.XLOOKUP(PRODUCTOS!A5,INVENTARIO!A5:A346,INVENTARIO!D5:D346)) -> 3,2 | D5: =IF(PRODUCTOS!A5="","",_xlfn.XLOOKUP(PRODUCTOS!A5,INVENTARIO!A5:A346,INVENTARIO!E5:E346)) -> 50 | G5: ROLLO
A6: LON-FRO-13OZ-1 | B6: =IF(PRODUCTOS!A6="","",_xlfn.XLOOKUP(PRODUCTOS!A6,INVENTARIO!A6:A347,INVENTARIO!C6:C347)) -> LONA FRONT 13 OZ | C6: =IF(PRODUCTOS!A6="","",_xlfn.XLOOKUP(PRODUCTOS!A6,INVENTARIO!A6:A347,INVENTARIO!D6:D347)) -> 1,6 | D6: =IF(PRODUCTOS!A6="","",_xlfn.XLOOKUP(PRODUCTOS!A6,INVENTARIO!A6:A347,INVENTARIO!E6:E347)) -> 50 | G6: ROLLO
A7: LON-FRO-13OZ-2 | B7: =IF(PRODUCTOS!A7="","",_xlfn.XLOOKUP(PRODUCTOS!A7,INVENTARIO!A7:A348,INVENTARIO!C7:C348)) -> LONA FRONT 13 OZ | C7: =IF(PRODUCTOS!A7="","",_xlfn.XLOOKUP(PRODUCTOS!A7,INVENTARIO!A7:A348,INVENTARIO!D7:D348)) -> 2,04 | D7: =IF(PRODUCTOS!A7="","",_xlfn.XLOOKUP(PRODUCTOS!A7,INVENTARIO!A7:A348,INVENTARIO!E7:E348)) -> 50 | G7: ROLLO
A8: LON-FRO-13OZ-3 | B8: =IF(PRODUCTOS!A8="","",_xlfn.XLOOKUP(PRODUCTOS!A8,INVENTARIO!A8:A349,INVENTARIO!C8:C349)) -> LONA FRONT 13 OZ | C8: =IF(PRODUCTOS!A8="","",_xlfn.XLOOKUP(PRODUCTOS!A8,INVENTARIO!A8:A349,INVENTARIO!D8:D349)) -> 2,04 | D8: =IF(PRODUCTOS!A8="","",_xlfn.XLOOKUP(PRODUCTOS!A8,INVENTARIO!A8:A349,INVENTARIO!E8:E349)) -> 100 | G8: ROLLO
A9: LON-FRO-13OZ-4 | B9: =IF(PRODUCTOS!A9="","",_xlfn.XLOOKUP(PRODUCTOS!A9,INVENTARIO!A9:A350,INVENTARIO!C9:C350)) -> LONA FRONT 13 OZ | C9: =IF(PRODUCTOS!A9="","",_xlfn.XLOOKUP(PRODUCTOS!A9,INVENTARIO!A9:A350,INVENTARIO!D9:D350)) -> 2,5 | D9: =IF(PRODUCTOS!A9="","",_xlfn.XLOOKUP(PRODUCTOS!A9,INVENTARIO!A9:A350,INVENTARIO!E9:E350)) -> 50 | G9: ROLLO
A10: LON-FRO-13OZ-5 | B10: =IF(PRODUCTOS!A10="","",_xlfn.XLOOKUP(PRODUCTOS!A10,INVENTARIO!A10:A351,INVENTARIO!C10:C351)) -> LONA FRONT 13 OZ | C10: =IF(PRODUCTOS!A10="","",_xlfn.XLOOKUP(PRODUCTOS!A10,INVENTARIO!A10:A351,INVENTARIO!D10:D351)) -> 2,5 | D10: =IF(PRODUCTOS!A10="","",_xlfn.XLOOKUP(PRODUCTOS!A10,INVENTARIO!A10:A351,INVENTARIO!E10:E351)) -> 100 | G10: ROLLO
A11: LON-FRO-13OZ-6 | B11: =IF(PRODUCTOS!A11="","",_xlfn.XLOOKUP(PRODUCTOS!A11,INVENTARIO!A11:A352,INVENTARIO!C11:C352)) -> LONA FRONT 13 OZ | C11: =IF(PRODUCTOS!A11="","",_xlfn.XLOOKUP(PRODUCTOS!A11,INVENTARIO!A11:A352,INVENTARIO!D11:D352)) -> 3,2 | D11: =IF(PRODUCTOS!A11="","",_xlfn.XLOOKUP(PRODUCTOS!A11,INVENTARIO!A11:A352,INVENTARIO!E11:E352)) -> 50 | G11: ROLLO
A12: LON-FRO-13OZ-7 | B12: =IF(PRODUCTOS!A12="","",_xlfn.XLOOKUP(PRODUCTOS!A12,INVENTARIO!A12:A353,INVENTARIO!C12:C353)) -> LONA FRONT 13 OZ | C12: =IF(PRODUCTOS!A12="","",_xlfn.XLOOKUP(PRODUCTOS!A12,INVENTARIO!A12:A353,INVENTARIO!D12:D353)) -> 3,2 | D12: =IF(PRODUCTOS!A12="","",_xlfn.XLOOKUP(PRODUCTOS!A12,INVENTARIO!A12:A353,INVENTARIO!E12:E353)) -> 100 | G12: ROLLO
A13: LON-ALT-RES-1 | B13: =IF(PRODUCTOS!A13="","",_xlfn.XLOOKUP(PRODUCTOS!A13,INVENTARIO!A13:A354,INVENTARIO!C13:C354)) -> LONA ALTA RESISTENCIA | C13: =IF(PRODUCTOS!A13="","",_xlfn.XLOOKUP(PRODUCTOS!A13,INVENTARIO!A13:A354,INVENTARIO!D13:D354)) -> 2,5 | D13: =IF(PRODUCTOS!A13="","",_xlfn.XLOOKUP(PRODUCTOS!A13,INVENTARIO!A13:A354,INVENTARIO!E13:E354)) -> 50 | G13: ROLLO
A14: LON-ALT-RES-2 | B14: =IF(PRODUCTOS!A14="","",_xlfn.XLOOKUP(PRODUCTOS!A14,INVENTARIO!A14:A355,INVENTARIO!C14:C355)) -> LONA ALTA RESISTENCIA | C14: =IF(PRODUCTOS!A14="","",_xlfn.XLOOKUP(PRODUCTOS!A14,INVENTARIO!A14:A355,INVENTARIO!D14:D355)) -> 3,2 | D14: =IF(PRODUCTOS!A14="","",_xlfn.XLOOKUP(PRODUCTOS!A14,INVENTARIO!A14:A355,INVENTARIO!E14:E355)) -> 50 | G14: ROLLO
A15: LON-MAT-13OZ-LAT-1 | B15: =IF(PRODUCTOS!A15="","",_xlfn.XLOOKUP(PRODUCTOS!A15,INVENTARIO!A15:A356,INVENTARIO!C15:C356)) -> LONA MATE 13 OZ LATEX | C15: =IF(PRODUCTOS!A15="","",_xlfn.XLOOKUP(PRODUCTOS!A15,INVENTARIO!A15:A356,INVENTARIO!D15:D356)) -> 1,52 | D15: =IF(PRODUCTOS!A15="","",_xlfn.XLOOKUP(PRODUCTOS!A15,INVENTARIO!A15:A356,INVENTARIO!E15:E356)) -> 50 | G15: ROLLO
... A320: FAB-350GR-1 | B320: =IF(PRODUCTOS!A320="","",_xlfn.XLOOKUP(PRODUCTOS!A320,INVENTARIO!A320:A661,INVENTARIO!C320:C661)) -> FABRIANO 350 GRS | C320: =IF(PRODUCTOS!A320="","",_xlfn.XLOOKUP(PRODUCTOS!A320,INVENTARIO!A320:A661,INVENTARIO!D320:D661)) -> 0 | D320: =IF(PRODUCTOS!A320="","",_xlfn.XLOOKUP(PRODUCTOS!A320,INVENTARIO!A320:A661,INVENTARIO!E320:E661)) -> 0 | G320: PIEZA

Sheet INVENTARIO
A1: ID MATERIAL | B1: PROVEEDOR | C1: MATERIAL | D1: MEDIDA | F1: EXISTENCIAS
D2: ANCHO | E2: LARGO | F2: ROLLO / HOJA / PIEZA / CARTUCHO | G2: M2 | H2: TOTAL | I2: STOCK MINIMO | J2: COSTO UNITARIO | K2: FECHA DE CADUCIDAD
A3: =_xlfn.TEXTJOIN("-",TRUE,Hoja2!A3:I3,1) -> LON-BAC-1 | B3: POLYVINILOS | C3: LONA BACKLITE | D3: 1,6 | E3: 50 | F3: 2 | G3: 20
A4: =_xlfn.TEXTJOIN("-",TRUE,Hoja2!A4:I4,2) -> LON-BAC-2 | B4: MEXTRAN | C4: LONA BACKLITE | D4: 2,5 | E4: 50
A5: =_xlfn.TEXTJOIN("-",TRUE,Hoja2!A5:I5,3) -> LON-BAC-3 | B5: MEXTRAN | C5: LONA BACKLITE | D5: 3,2 | E5: 50
A6: =_xlfn.TEXTJOIN("-",TRUE,Hoja2!A6:I6,1) -> LON-FRO-13OZ-1 | B6: POLYVINILOS | C6: LONA FRONT 13 OZ | D6: 1,6 | E6: 50
A7: =_xlfn.TEXTJOIN("-",TRUE,Hoja2!A7:I7,2) -> LON-FRO-13OZ-2 | B7: MEXTRAN | C7: LONA FRONT 13 OZ | D7: 2,04 | E7: 50
A8: =_xlfn.TEXTJOIN("-",TRUE,Hoja2!A8:I8,3) -> LON-FRO-13OZ-3 | B8: MEXTRAN | C8: LONA FRONT 13 OZ | D8: 2,04 | E8: 100
A9: =_xlfn.TEXTJOIN("-",TRUE,Hoja2!A9:I9,4) -> LON-FRO-13OZ-4 | B9: MEXTRAN | C9: LONA FRONT 13 OZ | D9: 2,5 | E9: 50
A10: =_xlfn.TEXTJOIN("-",TRUE,Hoja2!A10:I10,5) -> LON-FRO-13OZ-5 | B10: MEXTRAN | C10: LONA FRONT 13 OZ | D10: 2,5 | E10: 100
A11: =_xlfn.TEXTJOIN("-",TRUE,Hoja2!A11:I11,6) -> LON-FRO-13OZ-6 | B11: MEXTRAN | C11: LONA FRONT 13 OZ | D11: 3,2 | E11: 50
A12: =_xlfn.TEXTJOIN("-",TRUE,Hoja2!A12:I12,7) -> LON-FRO-13OZ-7 | B12: MEXTRAN | C12: LONA FRONT 13 OZ | D12: 3,2 | E12: 100
A13: =_xlfn.TEXTJOIN("-",TRUE,Hoja2!A13:I13,1) -> LON-ALT-RES-1 | B13: MEXTRAN | C13: LONA ALTA RESISTENCIA | D13: 2,5 | E13: 50
A14: =_xlfn.TEXTJOIN("-",TRUE,Hoja2!A14:I14,2) -> LON-ALT-RES-2 | B14: MEXTRAN | C14: LONA ALTA RESISTENCIA | D14: 3,2 | E14: 50
A15: =_xlfn.TEXTJOIN("-",TRUE,Hoja2!A15:I15,1) -> LON-MAT-13OZ-LAT-1 | B15: KRONALINE | C15: LONA MATE 13 OZ LATEX | D15: 1,52 | E15: 50
A16: =_xlfn.TEXTJOIN("-",TRUE,Hoja2!A16:I16,1) -> LON-MAT-13OZ-1 | B16: MEXTRAN | C16: LONA MATE 13 OZ | D16: 1,6 | E16: 50
A17: =_xlfn.TEXTJOIN("-",TRUE,Hoja2!A17:I17,2) -> LON-MAT-13OZ-2 | B17: MEXTRAN | C17: LONA MATE 13 OZ | D17: 2,5 | E17: 50
A18: =_xlfn.TEXTJOIN("-",TRUE,Hoja2!A18:I18,3) -> LON-MAT-13OZ-3 | B18: MEXTRAN | C18: LONA MATE 13 OZ | D18: 3,2 | E18: 50
A19: =_xlfn.TEXTJOIN("-",TRUE,Hoja2!A19:I19,4) -> LON-MAT-13OZ-4 | B19: MEXTRAN | C19: LONA MATE 13 OZ | D19: 3,2 | E19: 100
A20: =_xlfn.TEXTJOIN("-",TRUE,Hoja2!A20:I20,1) -> LON-MAT-13OZ-NEG-RES-NEG-1 | B20: MEXTRAN | C20: LONA MATE 13 OZ - RESP. NEGRO | D20: 2,5 | E20: 50
A21: =_xlfn.TEXTJOIN("-",TRUE,Hoja2!A21:I21,2) -> LON-MAT-13OZ-NEG-RES-NEG-2 | B21: MEXTRAN | C21: LONA MATE 13 OZ - RESP. NEGRO | D21: 2,5 | E21: 100
A22: =_xlfn.TEXTJOIN("-",TRUE,Hoja2!A22:I22,3) -> LON-MAT-13OZ-NEG-RES-NEG-3 | B22: MEXTRAN | C22: LONA MATE 13 OZ RESP. NEGRO | D22: 3,2 | E22: 50
A23: =_xlfn.TEXTJOIN("-",TRUE,Hoja2!A23:I23,4) -> LON-MAT-13OZ-NEG-RES-NEG-4 | B23: MEXTRAN | C23: LONA MATE 13 OZ - RESP. NEGRO | D23: 3,2 | E23: 100
A24: =_xlfn.TEXTJOIN("-",TRUE,Hoja2!A24:I24,1) -> LON-MES-1 | B24: MEXTRAN | C24: LONA MESH | D24: 1,6 | E24: 50
A25: =_xlfn.TEXTJOIN("-",TRUE,Hoja2!A25:I25,2) -> LON-MES-2 | B25: MEXTRAN | C25: LONA MESH | D25: 2.5 | E25: 50
A26: =_xlfn.TEXTJOIN("-",TRUE,Hoja2!A26:I26,3) -> LON-MES-3 | B26: MEXTRAN | C26: LONA MESH | D26: 2,5 | E26: 100
A27: =_xlfn.TEXTJOIN("-",TRUE,Hoja2!A27:I27,4) -> LON-MES-4 | B27: MEXTRAN | C27: LONA MESH | D27: 3,2 | E27: 50
A28: =_xlfn.TEXTJOIN("-",TRUE,Hoja2!A28:I28,5) -> LON-MES-5 | B28: MEXTRAN | C28: LONA MESH | D28: 3,2 | E28: 100
A29: =_xlfn.TEXTJOIN("-",TRUE,Hoja2!A29:I29,"BLU-BAC",1) -> PAP-BLU-BAC-1 | B29: MEXTRAN | C29: PAPEL BLUE BACK | D29: 1,55 | E29: 50
A30: =_xlfn.TEXTJOIN("-",TRUE,Hoja2!A30:I30,1) -> PAP-MAT-200GR-FOT-1 | B30: KRONALINE | C30: PAPEL MATE 200 GRS FOTOGRAFICO | D30: 1,52 | E30: 50
A31: =_xlfn.TEXTJOIN("-",TRUE,Hoja2!A31:I31,1) -> PAP-BRI-200GR-FOT-1 | B31: KRONALINE | C31: PAPEL BRILLANTE 200 GRS FOTOGRAFICO | D31: 1,52 | E31: 50
A32: =_xlfn.TEXTJOIN("-",TRUE,Hoja2!A32:I32,1) -> PAP-BAC-1 | B32: MEXTRAN | C32: PAPEL BACKLITE ( SEMIMATE) | D32: 1,52 | E32: 50
A33: =_xlfn.TEXTJOIN("-",TRUE,Hoja2!A33:I33,2) -> PAP-BAC-2 | B33: MEXTRAN | C33: PAPEL BACKLITE ( SEMIMATE) | D33: 1,52 | E33: 30
A34: =_xlfn.TEXTJOIN("-",TRUE,Hoja2!A34:I34,1) -> PAP-BAC-1 | B34: DT TEC | C34: PAPEL BACKLITE ( SEMIMATE) | D34: 1,52 | E34: 50
A35: =_xlfn.TEXTJOIN("-",TRUE,Hoja2!A35:I35,"SOL-KRO",1) -> PAP-SOL-KRO-1 | B35: KRONALINE | C35: PAPEL SOLVATEX KRONALINE | D35: 1,52 | E35: 50
A36: =_xlfn.TEXTJOIN("-",TRUE,Hoja2!A36:I36,1) -> PAP-CIT-1 | B36: MEXTRAN | C36: PAPEL CITYLIGHT | D36: 1,6 | E36: 50
A37: =_xlfn.TEXTJOIN("-",TRUE,Hoja2!A37:I37,2) -> PAP-CIT-2 | B37: MEXTRAN | C37: PAPEL CITYLIGHT | D37: 1,6 | E37: 100
A38: =_xlfn.TEXTJOIN("-",TRUE,Hoja2!A38:I38,1) -> TEL-SIN-DEL-1 | B38: DT TEC | C38: TELA SINTETICA DELGADA | D38: 1,52 | E38: 50
A39: =_xlfn.TEXTJOIN("-",TRUE,Hoja2!A39:I39,2) -> TEL-SIN-DEL-2 | B39: MEXTRAN | C39: TELA SINTETICA DELGADA | D39: 2,5 | E39: 50
A40: =_xlfn.TEXTJOIN("-",TRUE,Hoja2!A40:I40,3) -> TEL-SIN-DEL-3 | B40: MEXTRAN | C40: TELA SINTETICA DELGADA | D40: 3,2 | E40: 50
...

Sheet PROVEEDORES
B2: code | C2: legalName | D2: tradeName
B3: A | C3: ACERO SUECO PALME | D3: ACERO SUECO PALME
B4: B | C4: ACRILICOS PLASTITEC, S.A. DE C.V. | D4: PLASTITEC
B5: C | C5: AG ELECTRONICA
B6: D | C6: ALBUS LOANA JUAREZ SANTOYO | D6: ALBUS
B7: E | C7: AVANCE Y TECNOLOGIA EN PLASTICOS
B8: F | C8: BUNZL MEXICO | D8: BUNZL MEXICO
B9: G | C9: CASA SOMMER | D9: CASA SOMMER
B10: H | C10: COLED ILUMINACION | D10: COLED
B11: I | C11: DISTRIBUIDORA SAGARO DE MEXICO
B12: J | C12: DOCUPUEBLA | D12: DOCUPUEBLA
B13: K | C13: DT TEC | D13: DT TEC
B14: L | C14: EXHIVIT - SOLUCIONES EN RETAIL MAHEC | D14: EXHIVIT
B15: M | C15: FOCOS Y SISTEMAS DE ALUMBRADO S.A. DE C.V. | D15: FOCOS Y SISTEMAS
B16: N | C16: FRONTAGE COVERED DE MEXICO | D16: FRONTAGE
B17: O | C17: GRUPO OM | D17: GRUPO OM
B18: P | C18: HOME DEPOT | D18: HOME DEPOT
B19: Q | C19: HUMBERTO DILLAN ALBARRAN JACINTO | D19: DILLAN
B20: R | C20: INSUMOS FIA | D20: INSUMOS FIA
B21: S | C21: INSUMOS MAKRO | D21: INSUMOS MAKRO
B22: T | C22: KRONALINE | D22: KRONALINE
B23: U | C23: MARTEG - ELISEO CAMACHO UTRERA
B24: V | C24: MEXTRAN S.A. DE C.V. | D24: MEXTRAN
B25: W | C25: PAPELERIA LOZANO HERMANOS, S.A. DE C.V. | D25: LOZANO
B26: X | C26: PLASTI MUNDO | D26: PLASTI MUNDO
B27: Y | C27: POLYVINILOS - TIBURCIO RIVERA RAMIREZ | D27: POLYVINILOS
B28: Z | C28: QPOP - OCTAVIO ORDAZ | D28: QPOP OCTAVIO ORDAZ
B29: AA | C29: RODRIGO CARRANZA TREJO | D29: RODRIGO CARRANZA
B30: AB | C30: SALAMAN | D30: SALAMAN
B31: AC | C31: SERVIMERC - GABRIEL ISAAC ACOSTA LUNA | D31: SERVIMERC
B32: AD | C32: SPEC IMPORTACIONES | D32: SPEC
B33: AE | C33: TUBELITE DE MEXICO | D33: TUBELITE
B34: AF | C34: VINILOS Y GRAFICOS DIGITALES | D34: VINILOS Y GRAFICOS
D35: PELICULITAS BOPP
D36: SABIC POLYMERSHAPES
D37: KOLA LOKA

Sheet Hoja2
A3: =IF(ISNUMBER(SEARCH("LONA",INVENTARIO!C3)),"LON", IF(ISNUMBER(SEARCH("VINIL",INVENTARIO!C3)),"VIN", IF(ISNUMBER(SEARCH("KROMACOTE",INVENTARIO!C3)),"KRO", IF(ISNUMBER(SEARCH("STARDREAM",INVENTARIO!C3)),"STA", IF(ISNUMBER(SEARCH("DISPLAY",INVENTARIO!C3)),"DIS", IF(ISNUMBER(SEARCH("ROLL UP",INVENTARIO!C3)),"ROL-UP", IF(ISNUMBER(SEARCH("TRANSFER DE PAPEL",INVENTARIO!C3)),"TRA-PAP", IF(ISNUMBER(SEARCH("TRANSFER",INVENTARIO!C3)),"TRA",IF(ISNUMBER(SEARCH("KOLA LOKA",INVENTARIO!C3)),"KOL-LOK", IF(ISNUMBER(SEARCH("PETG",INVENTARIO!C3)),"PET", IF(ISNUMBER(SEARCH("OJILLO",INVENTARIO!C3)),"OJI", IF(ISNUMBER(SEARCH("COUCHE",INVENTARIO!C3)),"COU", IF(ISNUMBER(SEARCH("PANEL DE ALUMINIO",INVENTARIO!C3)),"PAN-ALU", IF(ISNUMBER(SEARCH("PVC",INVENTARIO!C3)),"PVC", IF(ISNUMBER(SEARCH("PAPEL",INVENTARIO!C3)),"PAP", IF(ISNUMBER(SEARCH("TELA",INVENTARIO!C3)),"TEL", IF(ISNUMBER(SEARCH("CARTULINA",INVENTARIO!C3)),"CAR", IF(OR(ISNUMBER(SEARCH("LAMINA",INVENTARIO!C3)),ISNUMBER(SEARCH("LÁMINA",INVENTARIO!C3)),ISNUMBER(SEARCH("LAMPARAS",INVENTARIO!C3))),"LAM", IF(ISNUMBER(SEARCH("ESTIRENO",INVENTARIO!C3)),"EST", IF(ISNUMBER(SEARCH("FOAMBOARD",INVENTARIO!C3)),"FOA", IF(ISNUMBER(SEARCH("SOLVENTE",INVENTARIO!C3)),"SOL", IF(ISNUMBER(SEARCH("TINTA",INVENTARIO!C3)),"TIN", IF(ISNUMBER(SEARCH("ACRILICO",INVENTARIO!C3)),"ACR", IF(ISNUMBER(SEARCH("MICROLED",INVENTARIO!C3)),"MIC", IF(ISNUMBER(SEARCH("LED",INVENTARIO!C3)),"LED", IF(ISNUMBER(SEARCH("FUENTE DE PODER",INVENTARIO!C3)),"FUE-POD", IF(ISNUMBER(SEARCH("PETG",INVENTARIO!C3)),"PET", IF(ISNUMBER(SEARCH("ALUMINIO",INVENTARIO!C3)),"ALU", IF(ISNUMBER(SEARCH("CANAL",INVENTARIO!C3)),"CAN", IF(ISNUMBER(SEARCH("ESCUADRA",INVENTARIO!C3)),"ESC", IF(ISNUMBER(SEARCH("SOPORTE",INVENTARIO!C3)),"SOP","OTR") )))))))))))))))))))))))))))))) -> LON | B3: =IF(ISNUMBER(SEARCH("CORTE",INVENTARIO!C3)),"COR", IF(ISNUMBER(SEARCH("CITYLIGHT",INVENTARIO!C3)),"CIT", IF(ISNUMBER(SEARCH("LINO",INVENTARIO!C3)),"LIN", IF(ISNUMBER(SEARCH("FABRIANO",INVENTARIO!C3)),"FAB", IF(ISNUMBER(SEARCH("SUNDANCE",INVENTARIO!C3)),"SUN", IF(ISNUMBER(SEARCH("SINTETICA",INVENTARIO!C3)),"SIN", IF(ISNUMBER(SEARCH("CONTROL",INVENTARIO!C3)),"CON", IF(ISNUMBER(SEARCH("TERMICO",INVENTARIO!C3)),"TER", IF(ISNUMBER(SEARCH("C-15",INVENTARIO!C3)),"C15", IF(ISNUMBER(SEARCH("C-20",INVENTARIO!C3)),"C20", IF(ISNUMBER(SEARCH("C-30",INVENTARIO!C3)),"C30", IF(ISNUMBER(SEARCH("C-40",INVENTARIO!C3)),"C40", IF(ISNUMBER(SEARCH("C-60",INVENTARIO!C3)),"C60", IF(ISNUMBER(SEARCH("C-80",INVENTARIO!C3)),"C80", IF(ISNUMBER(SEARCH("EQUIPO",INVENTARIO!C3)),"EQU", IF(ISNUMBER(SEARCH("FLOOR",INVENTARIO!C3)),"FLO", IF(ISNUMBER(SEARCH("CRISTAL",INVENTARIO!C3)),"CRI", IF(ISNUMBER(SEARCH(" SULFATADA",INVENTARIO!C14)),"SUL", IF(ISNUMBER(SEARCH("OPALINA",INVENTARIO!C3)),"OPA", IF(ISNUMBER(SEARCH("ADHERIBLE",INVENTARIO!C3)),"ADH", IF(ISNUMBER(SEARCH("MICRO",INVENTARIO!C3)),"MIC",""))))))))))))))))))))) | C3: =IF(ISNUMBER(SEARCH("PARED",INVENTARIO!C3)),"PAR", IF(ISNUMBER(SEARCH("FRONT",INVENTARIO!C3)),"FRO", IF(ISNUMBER(SEARCH("ALTA RESISTENCIA",INVENTARIO!C3)), "ALT-RES",IF(ISNUMBER(SEARCH("BACKLITE",INVENTARIO!C3)),"BAC", IF(ISNUMBER(SEARCH("MATE",INVENTARIO!C3)),"MAT", IF(ISNUMBER(SEARCH("MESH",INVENTARIO!C3)),"MES", IF(ISNUMBER(SEARCH("BRILLANTE",INVENTARIO!C3)),"BRI", IF(ISNUMBER(SEARCH("DELGADA",INVENTARIO!C3)),"DEL", IF(ISNUMBER(SEARCH("GRUESA",INVENTARIO!C3)),"GRU", IF(ISNUMBER(SEARCH("ESTATICO",INVENTARIO!C3)),"EST", IF(ISNUMBER(SEARCH("REFLECTIVO",INVENTARIO!C3)),"REF", IF(ISNUMBER(SEARCH("LX700",INVENTARIO!C3)),"LX7", IF(ISNUMBER(SEARCH("GRANDO",INVENTARIO!C3)),"GRA", IF(ISNUMBER(SEARCH("FB700",INVENTARIO!C3)),"FB7", IF(ISNUMBER(SEARCH("LX360",INVENTARIO!C3)),"LX3", IF(ISNUMBER(SEARCH("XEROX",INVENTARIO!C3)),"XER", IF(ISNUMBER(SEARCH("CEPILLADO",INVENTARIO!C3)),"CEP", IF(ISNUMBER(SEARCH("ESPEJO",INVENTARIO!C3)),"ESP", IF(ISNUMBER(SEARCH("10 PTS",INVENTARIO!C3)),"10PT", IF(ISNUMBER(SEARCH("12 PTS",INVENTARIO!C3)),"12PT", IF(ISNUMBER(SEARCH("14 PTS",INVENTARIO!C3)),"14PT", IF(ISNUMBER(SEARCH("CLASICO",INVENTARIO!C3)),"CLA", "")))))))))))))))))))))) -> BAC | D3: =IF(ISNUMBER(SEARCH("GRAN FORMATO",INVENTARIO!C3)),"GRA-FOR", IF(ISNUMBER(SEARCH("CAMA PLANA",INVENTARIO!C3)),"CAM-PLA", IF(ISNUMBER(SEARCH("GRADO INGENIERIA",INVENTARIO!C3)),"GRA-ING", IF(ISNUMBER(SEARCH("130 GRS",INVENTARIO!C3)),"130GR", IF(ISNUMBER(SEARCH("150 GRS",INVENTARIO!C3)),"150GR", IF(ISNUMBER(SEARCH("185 GRS",INVENTARIO!C3)),"185GR", IF(ISNUMBER(SEARCH("200 GRS",INVENTARIO!C3)),"200GR", IF(ISNUMBER(SEARCH("250 GRS",INVENTARIO!C3)),"250GR", IF(ISNUMBER(SEARCH("300 GRS",INVENTARIO!C3)),"300GR", IF(ISNUMBER(SEARCH("350 GRS",INVENTARIO!C3)),"350GR", IF(ISNUMBER(SEARCH("18 OZ",INVENTARIO!C3)),"18OZ", IF(ISNUMBER(SEARCH("15 OZ",INVENTARIO!C3)),"15OZ", IF(OR(ISNUMBER(SEARCH("13 OZ",INVENTARIO!C3)),ISNUMBER(SEARCH("13 ONZAS",INVENTARIO!C3))),"13OZ", IF(OR(ISNUMBER(SEARCH("9 OZ",INVENTARIO!C3)),ISNUMBER(SEARCH("9 ONZAS",INVENTARIO!C3))),"09OZ", IF(ISNUMBER(SEARCH("DOBLE CARA",INVENTARIO!C3)),"DOB-CAR", ""))))))))))))))) | E3: =IF(OR(ISNUMBER(SEARCH("TRANSPARENTE",INVENTARIO!C3)),ISNUMBER(SEARCH("TRANSPARENTES",INVENTARIO!C3))),"TRA", IF(OR(ISNUMBER(SEARCH("BLANCO",INVENTARIO!C3)),ISNUMBER(SEARCH("BCO",INVENTARIO!C3))),"BLA", IF(ISNUMBER(SEARCH("FOTOGRAFICO",INVENTARIO!C3)),"FOT", IF(ISNUMBER(SEARCH("MARFIL",INVENTARIO!C3)),"MAR", IF(ISNUMBER(SEARCH("VERDE",INVENTARIO!C3)),"VER", IF(ISNUMBER(SEARCH("MORADO",INVENTARIO!C3)),"MOR", IF(ISNUMBER(SEARCH("PLATA",INVENTARIO!C3)),"PLA", IF(ISNUMBER(SEARCH("ORO",INVENTARIO!C3)),"ORO", IF(ISNUMBER(SEARCH("AMARILLO",INVENTARIO!C3)),"AMA", IF(ISNUMBER(SEARCH("NARANJA",INVENTARIO!C3)),"NAR", IF(ISNUMBER(SEARCH("NEGRO",INVENTARIO!C3)),"NEG", IF(ISNUMBER(SEARCH("ROJO",INVENTARIO!C3)),"ROJ", IF(ISNUMBER(SEARCH("AZUL",INVENTARIO!C3)),"AZU",""))))))))))))) | F3: =IF(ISNUMBER(SEARCH("ARLON",INVENTARIO!C3)),"ARL", IF(ISNUMBER(SEARCH("SUNTHINKS",INVENTARIO!C3)),"SUN", IF(ISNUMBER(SEARCH("FRIO",INVENTARIO!C3)),"FRI", IF(ISNUMBER(SEARCH("CALIDO",INVENTARIO!C3)),"CAL", IF(ISNUMBER(SEARCH("CEPILLADO",INVENTARIO!C3)),"CEP", IF(ISNUMBER(SEARCH("ESPEJO",INVENTARIO!C3)),"ESP", "")))))) | G3: =IF(ISNUMBER(SEARCH("LATEX",INVENTARIO!C3)),"LAT", IF(ISNUMBER(SEARCH("RESP. NEGRO",INVENTARIO!C3)),"RES-NEG", IF(ISNUMBER(SEARCH("RESPALDO CAFE",INVENTARIO!C3)),"RES-CAF", IF(ISNUMBER(SEARCH("RESPALDO GRIS",INVENTARIO!C3)),"RES-GRI", IF(ISNUMBER(SEARCH("OPTICO",INVENTARIO!C3)),"OPT", IF(ISNUMBER(SEARCH("1,2 MM",INVENTARIO!C3)),"1MM2", IF(ISNUMBER(SEARCH("2 MM",INVENTARIO!C3)),"2MM", IF(ISNUMBER(SEARCH("3 MM",INVENTARIO!C3)),"3MM", IF(ISNUMBER(SEARCH("4 MM",INVENTARIO!C3)),"4MM", IF(ISNUMBER(SEARCH("5 MM",INVENTARIO!C3)),"5MM", IF(ISNUMBER(SEARCH("6 MM",INVENTARIO!C3)),"6MM", IF(ISNUMBER(SEARCH("9 MM",INVENTARIO!C3)),"9MM", IF(ISNUMBER(SEARCH("10 MM",INVENTARIO!C3)),"10MM",""))))))))))))) | H3: =IF(ISNUMBER(SEARCH("GAMA BAJA",INVENTARIO!C3)),"GAM-BAJ", IF(ISNUMBER(SEARCH("OPTIMIZADOR",INVENTARIO!C3)),"OPT", IF(ISNUMBER(SEARCH("OVERCOAT",INVENTARIO!C3)),"OVE", IF(ISNUMBER(SEARCH("WHITE",INVENTARIO!C3)),"WHI", IF(ISNUMBER(SEARCH("LIGHT CYAN",INVENTARIO!C3)),"LIG-CYA", IF(ISNUMBER(SEARCH("CYAN",INVENTARIO!C3)),"CYA", IF(ISNUMBER(SEARCH("LIGHT MAGENTA",INVENTARIO!C3)),"LIG-MAG", IF(ISNUMBER(SEARCH("MAGENTA",INVENTARIO!C3)),"MAG", IF(ISNUMBER(SEARCH("BLACK",INVENTARIO!C3)),"BLA", IF(ISNUMBER(SEARCH("YELLOW",INVENTARIO!C3)),"YEL", IF(ISNUMBER(SEARCH("2 DIODOS",INVENTARIO!C3)),"2DI", IF(ISNUMBER(SEARCH("3 DIODOS",INVENTARIO!C3)),"3DI", IF(OR(ISNUMBER(SEARCH("TRASLUCIDO",INVENTARIO!C3)),ISNUMBER(SEARCH("TRANSLUCIDO",INVENTARIO!C3))),"TRA", ""))))))))))))) | I3: =IF(ISNUMBER(SEARCH("SILED",INVENTARIO!C3)),"SI", IF(ISNUMBER(SEARCH("SYDEMEX",INVENTARIO!C3)),"SY", IF(ISNUMBER(SEARCH("ROHS",INVENTARIO!C3)),"RO", IF(ISNUMBER(SEARCH("RISHANG",INVENTARIO!C3)),"RS", IF(ISNUMBER(SEARCH("VYG",INVENTARIO!C3)),"VYG", IF(ISNUMBER(SEARCH("COLED",INVENTARIO!C3)),"CO",""))))))
A4: =IF(ISNUMBER(SEARCH("LONA",INVENTARIO!C4)),"LON", IF(ISNUMBER(SEARCH("VINIL",INVENTARIO!C4)),"VIN", IF(ISNUMBER(SEARCH("KROMACOTE",INVENTARIO!C4)),"KRO", IF(ISNUMBER(SEARCH("STARDREAM",INVENTARIO!C4)),"STA", IF(ISNUMBER(SEARCH("DISPLAY",INVENTARIO!C4)),"DIS", IF(ISNUMBER(SEARCH("ROLL UP",INVENTARIO!C4)),"ROL-UP", IF(ISNUMBER(SEARCH("TRANSFER DE PAPEL",INVENTARIO!C4)),"TRA-PAP", IF(ISNUMBER(SEARCH("TRANSFER",INVENTARIO!C4)),"TRA",IF(ISNUMBER(SEARCH("KOLA LOKA",INVENTARIO!C4)),"KOL-LOK", IF(ISNUMBER(SEARCH("PETG",INVENTARIO!C4)),"PET", IF(ISNUMBER(SEARCH("OJILLO",INVENTARIO!C4)),"OJI", IF(ISNUMBER(SEARCH("COUCHE",INVENTARIO!C4)),"COU", IF(ISNUMBER(SEARCH("PANEL DE ALUMINIO",INVENTARIO!C4)),"PAN-ALU", IF(ISNUMBER(SEARCH("PVC",INVENTARIO!C4)),"PVC", IF(ISNUMBER(SEARCH("PAPEL",INVENTARIO!C4)),"PAP", IF(ISNUMBER(SEARCH("TELA",INVENTARIO!C4)),"TEL", IF(ISNUMBER(SEARCH("CARTULINA",INVENTARIO!C4)),"CAR", IF(OR(ISNUMBER(SEARCH("LAMINA",INVENTARIO!C4)),ISNUMBER(SEARCH("LÁMINA",INVENTARIO!C4)),ISNUMBER(SEARCH("LAMPARAS",INVENTARIO!C4))),"LAM", IF(ISNUMBER(SEARCH("ESTIRENO",INVENTARIO!C4)),"EST", IF(ISNUMBER(SEARCH("FOAMBOARD",INVENTARIO!C4)),"FOA", IF(ISNUMBER(SEARCH("SOLVENTE",INVENTARIO!C4)),"SOL", IF(ISNUMBER(SEARCH("TINTA",INVENTARIO!C4)),"TIN", IF(ISNUMBER(SEARCH("ACRILICO",INVENTARIO!C4)),"ACR", IF(ISNUMBER(SEARCH("MICROLED",INVENTARIO!C4)),"MIC", IF(ISNUMBER(SEARCH("LED",INVENTARIO!C4)),"LED", IF(ISNUMBER(SEARCH("FUENTE DE PODER",INVENTARIO!C4)),"FUE-POD", IF(ISNUMBER(SEARCH("PETG",INVENTARIO!C4)),"PET", IF(ISNUMBER(SEARCH("ALUMINIO",INVENTARIO!C4)),"ALU", IF(ISNUMBER(SEARCH("CANAL",INVENTARIO!C4)),"CAN", IF(ISNUMBER(SEARCH("ESCUADRA",INVENTARIO!C4)),"ESC", IF(ISNUMBER(SEARCH("SOPORTE",INVENTARIO!C4)),"SOP","OTR") )))))))))))))))))))))))))))))) -> LON | B4: =IF(ISNUMBER(SEARCH("CORTE",INVENTARIO!C4)),"COR", IF(ISNUMBER(SEARCH("CITYLIGHT",INVENTARIO!C4)),"CIT", IF(ISNUMBER(SEARCH("LINO",INVENTARIO!C4)),"LIN", IF(ISNUMBER(SEARCH("FABRIANO",INVENTARIO!C4)),"FAB", IF(ISNUMBER(SEARCH("SUNDANCE",INVENTARIO!C4)),"SUN", IF(ISNUMBER(SEARCH("SINTETICA",INVENTARIO!C4)),"SIN", IF(ISNUMBER(SEARCH("CONTROL",INVENTARIO!C4)),"CON", IF(ISNUMBER(SEARCH("TERMICO",INVENTARIO!C4)),"TER", IF(ISNUMBER(SEARCH("C-15",INVENTARIO!C4)),"C15", IF(ISNUMBER(SEARCH("C-20",INVENTARIO!C4)),"C20", IF(ISNUMBER(SEARCH("C-30",INVENTARIO!C4)),"C30", IF(ISNUMBER(SEARCH("C-40",INVENTARIO!C4)),"C40", IF(ISNUMBER(SEARCH("C-60",INVENTARIO!C4)),"C60", IF(ISNUMBER(SEARCH("C-80",INVENTARIO!C4)),"C80", IF(ISNUMBER(SEARCH("EQUIPO",INVENTARIO!C4)),"EQU", IF(ISNUMBER(SEARCH("FLOOR",INVENTARIO!C4)),"FLO", IF(ISNUMBER(SEARCH("CRISTAL",INVENTARIO!C4)),"CRI", IF(ISNUMBER(SEARCH(" SULFATADA",INVENTARIO!C15)),"SUL", IF(ISNUMBER(SEARCH("OPALINA",INVENTARIO!C4)),"OPA", IF(ISNUMBER(SEARCH("ADHERIBLE",INVENTARIO!C4)),"ADH", IF(ISNUMBER(SEARCH("MICRO",INVENTARIO!C4)),"MIC",""))))))))))))))))))))) | C4: =IF(ISNUMBER(SEARCH("PARED",INVENTARIO!C4)),"PAR", IF(ISNUMBER(SEARCH("FRONT",INVENTARIO!C4)),"FRO", IF(ISNUMBER(SEARCH("ALTA RESISTENCIA",INVENTARIO!C4)), "ALT-RES",IF(ISNUMBER(SEARCH("BACKLITE",INVENTARIO!C4)),"BAC", IF(ISNUMBER(SEARCH("MATE",INVENTARIO!C4)),"MAT", IF(ISNUMBER(SEARCH("MESH",INVENTARIO!C4)),"MES", IF(ISNUMBER(SEARCH("BRILLANTE",INVENTARIO!C4)),"BRI", IF(ISNUMBER(SEARCH("DELGADA",INVENTARIO!C4)),"DEL", IF(ISNUMBER(SEARCH("GRUESA",INVENTARIO!C4)),"GRU", IF(ISNUMBER(SEARCH("ESTATICO",INVENTARIO!C4)),"EST", IF(ISNUMBER(SEARCH("REFLECTIVO",INVENTARIO!C4)),"REF", IF(ISNUMBER(SEARCH("LX700",INVENTARIO!C4)),"LX7", IF(ISNUMBER(SEARCH("GRANDO",INVENTARIO!C4)),"GRA", IF(ISNUMBER(SEARCH("FB700",INVENTARIO!C4)),"FB7", IF(ISNUMBER(SEARCH("LX360",INVENTARIO!C4)),"LX3", IF(ISNUMBER(SEARCH("XEROX",INVENTARIO!C4)),"XER", IF(ISNUMBER(SEARCH("CEPILLADO",INVENTARIO!C4)),"CEP", IF(ISNUMBER(SEARCH("ESPEJO",INVENTARIO!C4)),"ESP", IF(ISNUMBER(SEARCH("10 PTS",INVENTARIO!C4)),"10PT", IF(ISNUMBER(SEARCH("12 PTS",INVENTARIO!C4)),"12PT", IF(ISNUMBER(SEARCH("14 PTS",INVENTARIO!C4)),"14PT", IF(ISNUMBER(SEARCH("CLASICO",INVENTARIO!C4)),"CLA", "")))))))))))))))))))))) -> BAC | D4: =IF(ISNUMBER(SEARCH("GRAN FORMATO",INVENTARIO!C4)),"GRA-FOR", IF(ISNUMBER(SEARCH("CAMA PLANA",INVENTARIO!C4)),"CAM-PLA", IF(ISNUMBER(SEARCH("GRADO INGENIERIA",INVENTARIO!C4)),"GRA-ING", IF(ISNUMBER(SEARCH("130 GRS",INVENTARIO!C4)),"130GR", IF(ISNUMBER(SEARCH("150 GRS",INVENTARIO!C4)),"150GR", IF(ISNUMBER(SEARCH("185 GRS",INVENTARIO!C4)),"185GR", IF(ISNUMBER(SEARCH("200 GRS",INVENTARIO!C4)),"200GR", IF(ISNUMBER(SEARCH("250 GRS",INVENTARIO!C4)),"250GR", IF(ISNUMBER(SEARCH("300 GRS",INVENTARIO!C4)),"300GR", IF(ISNUMBER(SEARCH("350 GRS",INVENTARIO!C4)),"350GR", IF(ISNUMBER(SEARCH("18 OZ",INVENTARIO!C4)),"18OZ", IF(ISNUMBER(SEARCH("15 OZ",INVENTARIO!C4)),"15OZ", IF(OR(ISNUMBER(SEARCH("13 OZ",INVENTARIO!C4)),ISNUMBER(SEARCH("13 ONZAS",INVENTARIO!C4))),"13OZ", IF(OR(ISNUMBER(SEARCH("9 OZ",INVENTARIO!C4)),ISNUMBER(SEARCH("9 ONZAS",INVENTARIO!C4))),"09OZ", IF(ISNUMBER(SEARCH("DOBLE CARA",INVENTARIO!C4)),"DOB-CAR", ""))))))))))))))) | E4: =IF(OR(ISNUMBER(SEARCH("TRANSPARENTE",INVENTARIO!C4)),ISNUMBER(SEARCH("TRANSPARENTES",INVENTARIO!C4))),"TRA", IF(OR(ISNUMBER(SEARCH("BLANCO",INVENTARIO!C4)),ISNUMBER(SEARCH("BCO",INVENTARIO!C4))),"BLA", IF(ISNUMBER(SEARCH("FOTOGRAFICO",INVENTARIO!C4)),"FOT", IF(ISNUMBER(SEARCH("MARFIL",INVENTARIO!C4)),"MAR", IF(ISNUMBER(SEARCH("VERDE",INVENTARIO!C4)),"VER", IF(ISNUMBER(SEARCH("MORADO",INVENTARIO!C4)),"MOR", IF(ISNUMBER(SEARCH("PLATA",INVENTARIO!C4)),"PLA", IF(ISNUMBER(SEARCH("ORO",INVENTARIO!C4)),"ORO", IF(ISNUMBER(SEARCH("AMARILLO",INVENTARIO!C4)),"AMA", IF(ISNUMBER(SEARCH("NARANJA",INVENTARIO!C4)),"NAR", IF(ISNUMBER(SEARCH("NEGRO",INVENTARIO!C4)),"NEG", IF(ISNUMBER(SEARCH("ROJO",INVENTARIO!C4)),"ROJ", IF(ISNUMBER(SEARCH("AZUL",INVENTARIO!C4)),"AZU",""))))))))))))) | F4: =IF(ISNUMBER(SEARCH("ARLON",INVENTARIO!C4)),"ARL", IF(ISNUMBER(SEARCH("SUNTHINKS",INVENTARIO!C4)),"SUN", IF(ISNUMBER(SEARCH("FRIO",INVENTARIO!C4)),"FRI", IF(ISNUMBER(SEARCH("CALIDO",INVENTARIO!C4)),"CAL", IF(ISNUMBER(SEARCH("CEPILLADO",INVENTARIO!C4)),"CEP", IF(ISNUMBER(SEARCH("ESPEJO",INVENTARIO!C4)),"ESP", "")))))) | G4: =IF(ISNUMBER(SEARCH("LATEX",INVENTARIO!C4)),"LAT", IF(ISNUMBER(SEARCH("RESP. NEGRO",INVENTARIO!C4)),"RES-NEG", IF(ISNUMBER(SEARCH("RESPALDO CAFE",INVENTARIO!C4)),"RES-CAF", IF(ISNUMBER(SEARCH("RESPALDO GRIS",INVENTARIO!C4)),"RES-GRI", IF(ISNUMBER(SEARCH("OPTICO",INVENTARIO!C4)),"OPT", IF(ISNUMBER(SEARCH("1,2 MM",INVENTARIO!C4)),"1MM2", IF(ISNUMBER(SEARCH("2 MM",INVENTARIO!C4)),"2MM", IF(ISNUMBER(SEARCH("3 MM",INVENTARIO!C4)),"3MM", IF(ISNUMBER(SEARCH("4 MM",INVENTARIO!C4)),"4MM", IF(ISNUMBER(SEARCH("5 MM",INVENTARIO!C4)),"5MM", IF(ISNUMBER(SEARCH("6 MM",INVENTARIO!C4)),"6MM", IF(ISNUMBER(SEARCH("9 MM",INVENTARIO!C4)),"9MM", IF(ISNUMBER(SEARCH("10 MM",INVENTARIO!C4)),"10MM",""))))))))))))) | H4: =IF(ISNUMBER(SEARCH("GAMA BAJA",INVENTARIO!C4)),"GAM-BAJ", IF(ISNUMBER(SEARCH("OPTIMIZADOR",INVENTARIO!C4)),"OPT", IF(ISNUMBER(SEARCH("OVERCOAT",INVENTARIO!C4)),"OVE", IF(ISNUMBER(SEARCH("WHITE",INVENTARIO!C4)),"WHI", IF(ISNUMBER(SEARCH("LIGHT CYAN",INVENTARIO!C4)),"LIG-CYA", IF(ISNUMBER(SEARCH("CYAN",INVENTARIO!C4)),"CYA", IF(ISNUMBER(SEARCH("LIGHT MAGENTA",INVENTARIO!C4)),"LIG-MAG", IF(ISNUMBER(SEARCH("MAGENTA",INVENTARIO!C4)),"MAG", IF(ISNUMBER(SEARCH("BLACK",INVENTARIO!C4)),"BLA", IF(ISNUMBER(SEARCH("YELLOW",INVENTARIO!C4)),"YEL", IF(ISNUMBER(SEARCH("2 DIODOS",INVENTARIO!C4)),"2DI", IF(ISNUMBER(SEARCH("3 DIODOS",INVENTARIO!C4)),"3DI", IF(OR(ISNUMBER(SEARCH("TRASLUCIDO",INVENTARIO!C4)),ISNUMBER(SEARCH("TRANSLUCIDO",INVENTARIO!C4))),"TRA", ""))))))))))))) | I4: =IF(ISNUMBER(SEARCH("SILED",INVENTARIO!C4)),"SI", IF(ISNUMBER(SEARCH("SYDEMEX",INVENTARIO!C4)),"SY", IF(ISNUMBER(SEARCH("ROHS",INVENTARIO!C4)),"RO", IF(ISNUMBER(SEARCH("RISHANG",INVENTARIO!C4)),"RS", IF(ISNUMBER(SEARCH("VYG",INVENTARIO!C4)),"VYG", IF(ISNUMBER(SEARCH("COLED",INVENTARIO!C4)),"CO",""))))))
A5: =IF(ISNUMBER(SEARCH("LONA",INVENTARIO!C5)),"LON", IF(ISNUMBER(SEARCH("VINIL",INVENTARIO!C5)),"VIN", IF(ISNUMBER(SEARCH("KROMACOTE",INVENTARIO!C5)),"KRO", IF(ISNUMBER(SEARCH("STARDREAM",INVENTARIO!C5)),"STA", IF(ISNUMBER(SEARCH("DISPLAY",INVENTARIO!C5)),"DIS", IF(ISNUMBER(SEARCH("ROLL UP",INVENTARIO!C5)),"ROL-UP", IF(ISNUMBER(SEARCH("TRANSFER DE PAPEL",INVENTARIO!C5)),"TRA-PAP", IF(ISNUMBER(SEARCH("TRANSFER",INVENTARIO!C5)),"TRA",IF(ISNUMBER(SEARCH("KOLA LOKA",INVENTARIO!C5)),"KOL-LOK", IF(ISNUMBER(SEARCH("PETG",INVENTARIO!C5)),"PET", IF(ISNUMBER(SEARCH("OJILLO",INVENTARIO!C5)),"OJI", IF(ISNUMBER(SEARCH("COUCHE",INVENTARIO!C5)),"COU", IF(ISNUMBER(SEARCH("PANEL DE ALUMINIO",INVENTARIO!C5)),"PAN-ALU", IF(ISNUMBER(SEARCH("PVC",INVENTARIO!C5)),"PVC", IF(ISNUMBER(SEARCH("PAPEL",INVENTARIO!C5)),"PAP", IF(ISNUMBER(SEARCH("TELA",INVENTARIO!C5)),"TEL", IF(ISNUMBER(SEARCH("CARTULINA",INVENTARIO!C5)),"CAR", IF(OR(ISNUMBER(SEARCH("LAMINA",INVENTARIO!C5)),ISNUMBER(SEARCH("LÁMINA",INVENTARIO!C5)),ISNUMBER(SEARCH("LAMPARAS",INVENTARIO!C5))),"LAM", IF(ISNUMBER(SEARCH("ESTIRENO",INVENTARIO!C5)),"EST", IF(ISNUMBER(SEARCH("FOAMBOARD",INVENTARIO!C5)),"FOA", IF(ISNUMBER(SEARCH("SOLVENTE",INVENTARIO!C5)),"SOL", IF(ISNUMBER(SEARCH("TINTA",INVENTARIO!C5)),"TIN", IF(ISNUMBER(SEARCH("ACRILICO",INVENTARIO!C5)),"ACR", IF(ISNUMBER(SEARCH("MICROLED",INVENTARIO!C5)),"MIC", IF(ISNUMBER(SEARCH("LED",INVENTARIO!C5)),"LED", IF(ISNUMBER(SEARCH("FUENTE DE PODER",INVENTARIO!C5)),"FUE-POD", IF(ISNUMBER(SEARCH("PETG",INVENTARIO!C5)),"PET", IF(ISNUMBER(SEARCH("ALUMINIO",INVENTARIO!C5)),"ALU", IF(ISNUMBER(SEARCH("CANAL",INVENTARIO!C5)),"CAN", IF(ISNUMBER(SEARCH("ESCUADRA",INVENTARIO!C5)),"ESC", IF(ISNUMBER(SEARCH("SOPORTE",INVENTARIO!C5)),"SOP","OTR") )))))))))))))))))))))))))))))) -> LON | B5: =IF(ISNUMBER(SEARCH("CORTE",INVENTARIO!C5)),"COR", IF(ISNUMBER(SEARCH("CITYLIGHT",INVENTARIO!C5)),"CIT", IF(ISNUMBER(SEARCH("LINO",INVENTARIO!C5)),"LIN", IF(ISNUMBER(SEARCH("FABRIANO",INVENTARIO!C5)),"FAB", IF(ISNUMBER(SEARCH("SUNDANCE",INVENTARIO!C5)),"SUN", IF(ISNUMBER(SEARCH("SINTETICA",INVENTARIO!C5)),"SIN", IF(ISNUMBER(SEARCH("CONTROL",INVENTARIO!C5)),"CON", IF(ISNUMBER(SEARCH("TERMICO",INVENTARIO!C5)),"TER", IF(ISNUMBER(SEARCH("C-15",INVENTARIO!C5)),"C15", IF(ISNUMBER(SEARCH("C-20",INVENTARIO!C5)),"C20", IF(ISNUMBER(SEARCH("C-30",INVENTARIO!C5)),"C30", IF(ISNUMBER(SEARCH("C-40",INVENTARIO!C5)),"C40", IF(ISNUMBER(SEARCH("C-60",INVENTARIO!C5)),"C60", IF(ISNUMBER(SEARCH("C-80",INVENTARIO!C5)),"C80", IF(ISNUMBER(SEARCH("EQUIPO",INVENTARIO!C5)),"EQU", IF(ISNUMBER(SEARCH("FLOOR",INVENTARIO!C5)),"FLO", IF(ISNUMBER(SEARCH("CRISTAL",INVENTARIO!C5)),"CRI", IF(ISNUMBER(SEARCH(" SULFATADA",INVENTARIO!C16)),"SUL", IF(ISNUMBER(SEARCH("OPALINA",INVENTARIO!C5)),"OPA", IF(ISNUMBER(SEARCH("ADHERIBLE",INVENTARIO!C5)),"ADH", IF(ISNUMBER(SEARCH("MICRO",INVENTARIO!C5)),"MIC",""))))))))))))))))))))) | C5: =IF(ISNUMBER(SEARCH("PARED",INVENTARIO!C5)),"PAR", IF(ISNUMBER(SEARCH("FRONT",INVENTARIO!C5)),"FRO", IF(ISNUMBER(SEARCH("ALTA RESISTENCIA",INVENTARIO!C5)), "ALT-RES",IF(ISNUMBER(SEARCH("BACKLITE",INVENTARIO!C5)),"BAC", IF(ISNUMBER(SEARCH("MATE",INVENTARIO!C5)),"MAT", IF(ISNUMBER(SEARCH("MESH",INVENTARIO!C5)),"MES", IF(ISNUMBER(SEARCH("BRILLANTE",INVENTARIO!C5)),"BRI", IF(ISNUMBER(SEARCH("DELGADA",INVENTARIO!C5)),"DEL", IF(ISNUMBER(SEARCH("GRUESA",INVENTARIO!C5)),"GRU", IF(ISNUMBER(SEARCH("ESTATICO",INVENTARIO!C5)),"EST", IF(ISNUMBER(SEARCH("REFLECTIVO",INVENTARIO!C5)),"REF", IF(ISNUMBER(SEARCH("LX700",INVENTARIO!C5)),"LX7", IF(ISNUMBER(SEARCH("GRANDO",INVENTARIO!C5)),"GRA", IF(ISNUMBER(SEARCH("FB700",INVENTARIO!C5)),"FB7", IF(ISNUMBER(SEARCH("LX360",INVENTARIO!C5)),"LX3", IF(ISNUMBER(SEARCH("XEROX",INVENTARIO!C5)),"XER", IF(ISNUMBER(SEARCH("CEPILLADO",INVENTARIO!C5)),"CEP", IF(ISNUMBER(SEARCH("ESPEJO",INVENTARIO!C5)),"ESP", IF(ISNUMBER(SEARCH("10 PTS",INVENTARIO!C5)),"10PT", IF(ISNUMBER(SEARCH("12 PTS",INVENTARIO!C5)),"12PT", IF(ISNUMBER(SEARCH("14 PTS",INVENTARIO!C5)),"14PT", IF(ISNUMBER(SEARCH("CLASICO",INVENTARIO!C5)),"CLA", "")))))))))))))))))))))) -> BAC | D5: =IF(ISNUMBER(SEARCH("GRAN FORMATO",INVENTARIO!C5)),"GRA-FOR", IF(ISNUMBER(SEARCH("CAMA PLANA",INVENTARIO!C5)),"CAM-PLA", IF(ISNUMBER(SEARCH("GRADO INGENIERIA",INVENTARIO!C5)),"GRA-ING", IF(ISNUMBER(SEARCH("130 GRS",INVENTARIO!C5)),"130GR", IF(ISNUMBER(SEARCH("150 GRS",INVENTARIO!C5)),"150GR", IF(ISNUMBER(SEARCH("185 GRS",INVENTARIO!C5)),"185GR", IF(ISNUMBER(SEARCH("200 GRS",INVENTARIO!C5)),"200GR", IF(ISNUMBER(SEARCH("250 GRS",INVENTARIO!C5)),"250GR", IF(ISNUMBER(SEARCH("300 GRS",INVENTARIO!C5)),"300GR", IF(ISNUMBER(SEARCH("350 GRS",INVENTARIO!C5)),"350GR", IF(ISNUMBER(SEARCH("18 OZ",INVENTARIO!C5)),"18OZ", IF(ISNUMBER(SEARCH("15 OZ",INVENTARIO!C5)),"15OZ", IF(OR(ISNUMBER(SEARCH("13 OZ",INVENTARIO!C5)),ISNUMBER(SEARCH("13 ONZAS",INVENTARIO!C5))),"13OZ", IF(OR(ISNUMBER(SEARCH("9 OZ",INVENTARIO!C5)),ISNUMBER(SEARCH("9 ONZAS",INVENTARIO!C5))),"09OZ", IF(ISNUMBER(SEARCH("DOBLE CARA",INVENTARIO!C5)),"DOB-CAR", ""))))))))))))))) | E5: =IF(OR(ISNUMBER(SEARCH("TRANSPARENTE",INVENTARIO!C5)),ISNUMBER(SEARCH("TRANSPARENTES",INVENTARIO!C5))),"TRA", IF(OR(ISNUMBER(SEARCH("BLANCO",INVENTARIO!C5)),ISNUMBER(SEARCH("BCO",INVENTARIO!C5))),"BLA", IF(ISNUMBER(SEARCH("FOTOGRAFICO",INVENTARIO!C5)),"FOT", IF(ISNUMBER(SEARCH("MARFIL",INVENTARIO!C5)),"MAR", IF(ISNUMBER(SEARCH("VERDE",INVENTARIO!C5)),"VER", IF(ISNUMBER(SEARCH("MORADO",INVENTARIO!C5)),"MOR", IF(ISNUMBER(SEARCH("PLATA",INVENTARIO!C5)),"PLA", IF(ISNUMBER(SEARCH("ORO",INVENTARIO!C5)),"ORO", IF(ISNUMBER(SEARCH("AMARILLO",INVENTARIO!C5)),"AMA", IF(ISNUMBER(SEARCH("NARANJA",INVENTARIO!C5)),"NAR", IF(ISNUMBER(SEARCH("NEGRO",INVENTARIO!C5)),"NEG", IF(ISNUMBER(SEARCH("ROJO",INVENTARIO!C5)),"ROJ", IF(ISNUMBER(SEARCH("AZUL",INVENTARIO!C5)),"AZU",""))))))))))))) | F5: =IF(ISNUMBER(SEARCH("ARLON",INVENTARIO!C5)),"ARL", IF(ISNUMBER(SEARCH("SUNTHINKS",INVENTARIO!C5)),"SUN", IF(ISNUMBER(SEARCH("FRIO",INVENTARIO!C5)),"FRI", IF(ISNUMBER(SEARCH("CALIDO",INVENTARIO!C5)),"CAL", IF(ISNUMBER(SEARCH("CEPILLADO",INVENTARIO!C5)),"CEP", IF(ISNUMBER(SEARCH("ESPEJO",INVENTARIO!C5)),"ESP", "")))))) | G5: =IF(ISNUMBER(SEARCH("LATEX",INVENTARIO!C5)),"LAT", IF(ISNUMBER(SEARCH("RESP. NEGRO",INVENTARIO!C5)),"RES-NEG", IF(ISNUMBER(SEARCH("RESPALDO CAFE",INVENTARIO!C5)),"RES-CAF", IF(ISNUMBER(SEARCH("RESPALDO GRIS",INVENTARIO!C5)),"RES-GRI", IF(ISNUMBER(SEARCH("OPTICO",INVENTARIO!C5)),"OPT", IF(ISNUMBER(SEARCH("1,2 MM",INVENTARIO!C5)),"1MM2", IF(ISNUMBER(SEARCH("2 MM",INVENTARIO!C5)),"2MM", IF(ISNUMBER(SEARCH("3 MM",INVENTARIO!C5)),"3MM", IF(ISNUMBER(SEARCH("4 MM",INVENTARIO!C5)),"4MM", IF(ISNUMBER(SEARCH("5 MM",INVENTARIO!C5)),"5MM", IF(ISNUMBER(SEARCH("6 MM",INVENTARIO!C5)),"6MM", IF(ISNUMBER(SEARCH("9 MM",INVENTARIO!C5)),"9MM", IF(ISNUMBER(SEARCH("10 MM",INVENTARIO!C5)),"10MM",""))))))))))))) | H5: =IF(ISNUMBER(SEARCH("GAMA BAJA",INVENTARIO!C5)),"GAM-BAJ", IF(ISNUMBER(SEARCH("OPTIMIZADOR",INVENTARIO!C5)),"OPT", IF(ISNUMBER(SEARCH("OVERCOAT",INVENTARIO!C5)),"OVE", IF(ISNUMBER(SEARCH("WHITE",INVENTARIO!C5)),"WHI", IF(ISNUMBER(SEARCH("LIGHT CYAN",INVENTARIO!C5)),"LIG-CYA", IF(ISNUMBER(SEARCH("CYAN",INVENTARIO!C5)),"CYA", IF(ISNUMBER(SEARCH("LIGHT MAGENTA",INVENTARIO!C5)),"LIG-MAG", IF(ISNUMBER(SEARCH("MAGENTA",INVENTARIO!C5)),"MAG", IF(ISNUMBER(SEARCH("BLACK",INVENTARIO!C5)),"BLA", IF(ISNUMBER(SEARCH("YELLOW",INVENTARIO!C5)),"YEL", IF(ISNUMBER(SEARCH("2 DIODOS",INVENTARIO!C5)),"2DI", IF(ISNUMBER(SEARCH("3 DIODOS",INVENTARIO!C5)),"3DI", IF(OR(ISNUMBER(SEARCH("TRASLUCIDO",INVENTARIO!C5)),ISNUMBER(SEARCH("TRANSLUCIDO",INVENTARIO!C5))),"TRA", ""))))))))))))) | I5: =IF(ISNUMBER(SEARCH("SILED",INVENTARIO!C5)),"SI", IF(ISNUMBER(SEARCH("SYDEMEX",INVENTARIO!C5)),"SY", IF(ISNUMBER(SEARCH("ROHS",INVENTARIO!C5)),"RO", IF(ISNUMBER(SEARCH("RISHANG",INVENTARIO!C5)),"RS", IF(ISNUMBER(SEARCH("VYG",INVENTARIO!C5)),"VYG", IF(ISNUMBER(SEARCH("COLED",INVENTARIO!C5)),"CO",""))))))
A6: =IF(ISNUMBER(SEARCH("LONA",INVENTARIO!C6)),"LON", IF(ISNUMBER(SEARCH("VINIL",INVENTARIO!C6)),"VIN", IF(ISNUMBER(SEARCH("KROMACOTE",INVENTARIO!C6)),"KRO", IF(ISNUMBER(SEARCH("STARDREAM",INVENTARIO!C6)),"STA", IF(ISNUMBER(SEARCH("DISPLAY",INVENTARIO!C6)),"DIS", IF(ISNUMBER(SEARCH("ROLL UP",INVENTARIO!C6)),"ROL-UP", IF(ISNUMBER(SEARCH("TRANSFER DE PAPEL",INVENTARIO!C6)),"TRA-PAP", IF(ISNUMBER(SEARCH("TRANSFER",INVENTARIO!C6)),"TRA",IF(ISNUMBER(SEARCH("KOLA LOKA",INVENTARIO!C6)),"KOL-LOK", IF(ISNUMBER(SEARCH("PETG",INVENTARIO!C6)),"PET", IF(ISNUMBER(SEARCH("OJILLO",INVENTARIO!C6)),"OJI", IF(ISNUMBER(SEARCH("COUCHE",INVENTARIO!C6)),"COU", IF(ISNUMBER(SEARCH("PANEL DE ALUMINIO",INVENTARIO!C6)),"PAN-ALU", IF(ISNUMBER(SEARCH("PVC",INVENTARIO!C6)),"PVC", IF(ISNUMBER(SEARCH("PAPEL",INVENTARIO!C6)),"PAP", IF(ISNUMBER(SEARCH("TELA",INVENTARIO!C6)),"TEL", IF(ISNUMBER(SEARCH("CARTULINA",INVENTARIO!C6)),"CAR", IF(OR(ISNUMBER(SEARCH("LAMINA",INVENTARIO!C6)),ISNUMBER(SEARCH("LÁMINA",INVENTARIO!C6)),ISNUMBER(SEARCH("LAMPARAS",INVENTARIO!C6))),"LAM", IF(ISNUMBER(SEARCH("ESTIRENO",INVENTARIO!C6)),"EST", IF(ISNUMBER(SEARCH("FOAMBOARD",INVENTARIO!C6)),"FOA", IF(ISNUMBER(SEARCH("SOLVENTE",INVENTARIO!C6)),"SOL", IF(ISNUMBER(SEARCH("TINTA",INVENTARIO!C6)),"TIN", IF(ISNUMBER(SEARCH("ACRILICO",INVENTARIO!C6)),"ACR", IF(ISNUMBER(SEARCH("MICROLED",INVENTARIO!C6)),"MIC", IF(ISNUMBER(SEARCH("LED",INVENTARIO!C6)),"LED", IF(ISNUMBER(SEARCH("FUENTE DE PODER",INVENTARIO!C6)),"FUE-POD", IF(ISNUMBER(SEARCH("PETG",INVENTARIO!C6)),"PET", IF(ISNUMBER(SEARCH("ALUMINIO",INVENTARIO!C6)),"ALU", IF(ISNUMBER(SEARCH("CANAL",INVENTARIO!C6)),"CAN", IF(ISNUMBER(SEARCH("ESCUADRA",INVENTARIO!C6)),"ESC", IF(ISNUMBER(SEARCH("SOPORTE",INVENTARIO!C6)),"SOP","OTR") )))))))))))))))))))))))))))))) -> LON | B6: =IF(ISNUMBER(SEARCH("CORTE",INVENTARIO!C6)),"COR", IF(ISNUMBER(SEARCH("CITYLIGHT",INVENTARIO!C6)),"CIT", IF(ISNUMBER(SEARCH("LINO",INVENTARIO!C6)),"LIN", IF(ISNUMBER(SEARCH("FABRIANO",INVENTARIO!C6)),"FAB", IF(ISNUMBER(SEARCH("SUNDANCE",INVENTARIO!C6)),"SUN", IF(ISNUMBER(SEARCH("SINTETICA",INVENTARIO!C6)),"SIN", IF(ISNUMBER(SEARCH("CONTROL",INVENTARIO!C6)),"CON", IF(ISNUMBER(SEARCH("TERMICO",INVENTARIO!C6)),"TER", IF(ISNUMBER(SEARCH("C-15",INVENTARIO!C6)),"C15", IF(ISNUMBER(SEARCH("C-20",INVENTARIO!C6)),"C20", IF(ISNUMBER(SEARCH("C-30",INVENTARIO!C6)),"C30", IF(ISNUMBER(SEARCH("C-40",INVENTARIO!C6)),"C40", IF(ISNUMBER(SEARCH("C-60",INVENTARIO!C6)),"C60", IF(ISNUMBER(SEARCH("C-80",INVENTARIO!C6)),"C80", IF(ISNUMBER(SEARCH("EQUIPO",INVENTARIO!C6)),"EQU", IF(ISNUMBER(SEARCH("FLOOR",INVENTARIO!C6)),"FLO", IF(ISNUMBER(SEARCH("CRISTAL",INVENTARIO!C6)),"CRI", IF(ISNUMBER(SEARCH(" SULFATADA",INVENTARIO!C17)),"SUL", IF(ISNUMBER(SEARCH("OPALINA",INVENTARIO!C6)),"OPA", IF(ISNUMBER(SEARCH("ADHERIBLE",INVENTARIO!C6)),"ADH", IF(ISNUMBER(SEARCH("MICRO",INVENTARIO!C6)),"MIC",""))))))))))))))))))))) | C6: =IF(ISNUMBER(SEARCH("PARED",INVENTARIO!C6)),"PAR", IF(ISNUMBER(SEARCH("FRONT",INVENTARIO!C6)),"FRO", IF(ISNUMBER(SEARCH("ALTA RESISTENCIA",INVENTARIO!C6)), "ALT-RES",IF(ISNUMBER(SEARCH("BACKLITE",INVENTARIO!C6)),"BAC", IF(ISNUMBER(SEARCH("MATE",INVENTARIO!C6)),"MAT", IF(ISNUMBER(SEARCH("MESH",INVENTARIO!C6)),"MES", IF(ISNUMBER(SEARCH("BRILLANTE",INVENTARIO!C6)),"BRI", IF(ISNUMBER(SEARCH("DELGADA",INVENTARIO!C6)),"DEL", IF(ISNUMBER(SEARCH("GRUESA",INVENTARIO!C6)),"GRU", IF(ISNUMBER(SEARCH("ESTATICO",INVENTARIO!C6)),"EST", IF(ISNUMBER(SEARCH("REFLECTIVO",INVENTARIO!C6)),"REF", IF(ISNUMBER(SEARCH("LX700",INVENTARIO!C6)),"LX7", IF(ISNUMBER(SEARCH("GRANDO",INVENTARIO!C6)),"GRA", IF(ISNUMBER(SEARCH("FB700",INVENTARIO!C6)),"FB7", IF(ISNUMBER(SEARCH("LX360",INVENTARIO!C6)),"LX3", IF(ISNUMBER(SEARCH("XEROX",INVENTARIO!C6)),"XER", IF(ISNUMBER(SEARCH("CEPILLADO",INVENTARIO!C6)),"CEP", IF(ISNUMBER(SEARCH("ESPEJO",INVENTARIO!C6)),"ESP", IF(ISNUMBER(SEARCH("10 PTS",INVENTARIO!C6)),"10PT", IF(ISNUMBER(SEARCH("12 PTS",INVENTARIO!C6)),"12PT", IF(ISNUMBER(SEARCH("14 PTS",INVENTARIO!C6)),"14PT", IF(ISNUMBER(SEARCH("CLASICO",INVENTARIO!C6)),"CLA", "")))))))))))))))))))))) -> FRO | D6: =IF(ISNUMBER(SEARCH("GRAN FORMATO",INVENTARIO!C6)),"GRA-FOR", IF(ISNUMBER(SEARCH("CAMA PLANA",INVENTARIO!C6)),"CAM-PLA", IF(ISNUMBER(SEARCH("GRADO INGENIERIA",INVENTARIO!C6)),"GRA-ING", IF(ISNUMBER(SEARCH("130 GRS",INVENTARIO!C6)),"130GR", IF(ISNUMBER(SEARCH("150 GRS",INVENTARIO!C6)),"150GR", IF(ISNUMBER(SEARCH("185 GRS",INVENTARIO!C6)),"185GR", IF(ISNUMBER(SEARCH("200 GRS",INVENTARIO!C6)),"200GR", IF(ISNUMBER(SEARCH("250 GRS",INVENTARIO!C6)),"250GR", IF(ISNUMBER(SEARCH("300 GRS",INVENTARIO!C6)),"300GR", IF(ISNUMBER(SEARCH("350 GRS",INVENTARIO!C6)),"350GR", IF(ISNUMBER(SEARCH("18 OZ",INVENTARIO!C6)),"18OZ", IF(ISNUMBER(SEARCH("15 OZ",INVENTARIO!C6)),"15OZ", IF(OR(ISNUMBER(SEARCH("13 OZ",INVENTARIO!C6)),ISNUMBER(SEARCH("13 ONZAS",INVENTARIO!C6))),"13OZ", IF(OR(ISNUMBER(SEARCH("9 OZ",INVENTARIO!C6)),ISNUMBER(SEARCH("9 ONZAS",INVENTARIO!C6))),"09OZ", IF(ISNUMBER(SEARCH("DOBLE CARA",INVENTARIO!C6)),"DOB-CAR", ""))))))))))))))) -> 13OZ | E6: =IF(OR(ISNUMBER(SEARCH("TRANSPARENTE",INVENTARIO!C6)),ISNUMBER(SEARCH("TRANSPARENTES",INVENTARIO!C6))),"TRA", IF(OR(ISNUMBER(SEARCH("BLANCO",INVENTARIO!C6)),ISNUMBER(SEARCH("BCO",INVENTARIO!C6))),"BLA", IF(ISNUMBER(SEARCH("FOTOGRAFICO",INVENTARIO!C6)),"FOT", IF(ISNUMBER(SEARCH("MARFIL",INVENTARIO!C6)),"MAR", IF(ISNUMBER(SEARCH("VERDE",INVENTARIO!C6)),"VER", IF(ISNUMBER(SEARCH("MORADO",INVENTARIO!C6)),"MOR", IF(ISNUMBER(SEARCH("PLATA",INVENTARIO!C6)),"PLA", IF(ISNUMBER(SEARCH("ORO",INVENTARIO!C6)),"ORO", IF(ISNUMBER(SEARCH("AMARILLO",INVENTARIO!C6)),"AMA", IF(ISNUMBER(SEARCH("NARANJA",INVENTARIO!C6)),"NAR", IF(ISNUMBER(SEARCH("NEGRO",INVENTARIO!C6)),"NEG", IF(ISNUMBER(SEARCH("ROJO",INVENTARIO!C6)),"ROJ", IF(ISNUMBER(SEARCH("AZUL",INVENTARIO!C6)),"AZU",""))))))))))))) | F6: =IF(ISNUMBER(SEARCH("ARLON",INVENTARIO!C6)),"ARL", IF(ISNUMBER(SEARCH("SUNTHINKS",INVENTARIO!C6)),"SUN", IF(ISNUMBER(SEARCH("FRIO",INVENTARIO!C6)),"FRI", IF(ISNUMBER(SEARCH("CALIDO",INVENTARIO!C6)),"CAL", IF(ISNUMBER(SEARCH("CEPILLADO",INVENTARIO!C6)),"CEP", IF(ISNUMBER(SEARCH("ESPEJO",INVENTARIO!C6)),"ESP", "")))))) | G6: =IF(ISNUMBER(SEARCH("LATEX",INVENTARIO!C6)),"LAT", IF(ISNUMBER(SEARCH("RESP. NEGRO",INVENTARIO!C6)),"RES-NEG", IF(ISNUMBER(SEARCH("RESPALDO CAFE",INVENTARIO!C6)),"RES-CAF", IF(ISNUMBER(SEARCH("RESPALDO GRIS",INVENTARIO!C6)),"RES-GRI", IF(ISNUMBER(SEARCH("OPTICO",INVENTARIO!C6)),"OPT", IF(ISNUMBER(SEARCH("1,2 MM",INVENTARIO!C6)),"1MM2", IF(ISNUMBER(SEARCH("2 MM",INVENTARIO!C6)),"2MM", IF(ISNUMBER(SEARCH("3 MM",INVENTARIO!C6)),"3MM", IF(ISNUMBER(SEARCH("4 MM",INVENTARIO!C6)),"4MM", IF(ISNUMBER(SEARCH("5 MM",INVENTARIO!C6)),"5MM", IF(ISNUMBER(SEARCH("6 MM",INVENTARIO!C6)),"6MM", IF(ISNUMBER(SEARCH("9 MM",INVENTARIO!C6)),"9MM", IF(ISNUMBER(SEARCH("10 MM",INVENTARIO!C6)),"10MM",""))))))))))))) | H6: =IF(ISNUMBER(SEARCH("GAMA BAJA",INVENTARIO!C6)),"GAM-BAJ", IF(ISNUMBER(SEARCH("OPTIMIZADOR",INVENTARIO!C6)),"OPT", IF(ISNUMBER(SEARCH("OVERCOAT",INVENTARIO!C6)),"OVE", IF(ISNUMBER(SEARCH("WHITE",INVENTARIO!C6)),"WHI", IF(ISNUMBER(SEARCH("LIGHT CYAN",INVENTARIO!C6)),"LIG-CYA", IF(ISNUMBER(SEARCH("CYAN",INVENTARIO!C6)),"CYA", IF(ISNUMBER(SEARCH("LIGHT MAGENTA",INVENTARIO!C6)),"LIG-MAG", IF(ISNUMBER(SEARCH("MAGENTA",INVENTARIO!C6)),"MAG", IF(ISNUMBER(SEARCH("BLACK",INVENTARIO!C6)),"BLA", IF(ISNUMBER(SEARCH("YELLOW",INVENTARIO!C6)),"YEL", IF(ISNUMBER(SEARCH("2 DIODOS",INVENTARIO!C6)),"2DI", IF(ISNUMBER(SEARCH("3 DIODOS",INVENTARIO!C6)),"3DI", IF(OR(ISNUMBER(SEARCH("TRASLUCIDO",INVENTARIO!C6)),ISNUMBER(SEARCH("TRANSLUCIDO",INVENTARIO!C6))),"TRA", ""))))))))))))) | I6: =IF(ISNUMBER(SEARCH("SILED",INVENTARIO!C6)),"SI", IF(ISNUMBER(SEARCH("SYDEMEX",INVENTARIO!C6)),"SY", IF(ISNUMBER(SEARCH("ROHS",INVENTARIO!C6)),"RO", IF(ISNUMBER(SEARCH("RISHANG",INVENTARIO!C6)),"RS", IF(ISNUMBER(SEARCH("VYG",INVENTARIO!C6)),"VYG", IF(ISNUMBER(SEARCH("COLED",INVENTARIO!C6)),"CO",""))))))
A7: =IF(ISNUMBER(SEARCH("LONA",INVENTARIO!C7)),"LON", IF(ISNUMBER(SEARCH("VINIL",INVENTARIO!C7)),"VIN", IF(ISNUMBER(SEARCH("KROMACOTE",INVENTARIO!C7)),"KRO", IF(ISNUMBER(SEARCH("STARDREAM",INVENTARIO!C7)),"STA", IF(ISNUMBER(SEARCH("DISPLAY",INVENTARIO!C7)),"DIS", IF(ISNUMBER(SEARCH("ROLL UP",INVENTARIO!C7)),"ROL-UP", IF(ISNUMBER(SEARCH("TRANSFER DE PAPEL",INVENTARIO!C7)),"TRA-PAP", IF(ISNUMBER(SEARCH("TRANSFER",INVENTARIO!C7)),"TRA",IF(ISNUMBER(SEARCH("KOLA LOKA",INVENTARIO!C7)),"KOL-LOK", IF(ISNUMBER(SEARCH("PETG",INVENTARIO!C7)),"PET", IF(ISNUMBER(SEARCH("OJILLO",INVENTARIO!C7)),"OJI", IF(ISNUMBER(SEARCH("COUCHE",INVENTARIO!C7)),"COU", IF(ISNUMBER(SEARCH("PANEL DE ALUMINIO",INVENTARIO!C7)),"PAN-ALU", IF(ISNUMBER(SEARCH("PVC",INVENTARIO!C7)),"PVC", IF(ISNUMBER(SEARCH("PAPEL",INVENTARIO!C7)),"PAP", IF(ISNUMBER(SEARCH("TELA",INVENTARIO!C7)),"TEL", IF(ISNUMBER(SEARCH("CARTULINA",INVENTARIO!C7)),"CAR", IF(OR(ISNUMBER(SEARCH("LAMINA",INVENTARIO!C7)),ISNUMBER(SEARCH("LÁMINA",INVENTARIO!C7)),ISNUMBER(SEARCH("LAMPARAS",INVENTARIO!C7))),"LAM", IF(ISNUMBER(SEARCH("ESTIRENO",INVENTARIO!C7)),"EST", IF(ISNUMBER(SEARCH("FOAMBOARD",INVENTARIO!C7)),"FOA", IF(ISNUMBER(SEARCH("SOLVENTE",INVENTARIO!C7)),"SOL", IF(ISNUMBER(SEARCH("TINTA",INVENTARIO!C7)),"TIN", IF(ISNUMBER(SEARCH("ACRILICO",INVENTARIO!C7)),"ACR", IF(ISNUMBER(SEARCH("MICROLED",INVENTARIO!C7)),"MIC", IF(ISNUMBER(SEARCH("LED",INVENTARIO!C7)),"LED", IF(ISNUMBER(SEARCH("FUENTE DE PODER",INVENTARIO!C7)),"FUE-POD", IF(ISNUMBER(SEARCH("PETG",INVENTARIO!C7)),"PET", IF(ISNUMBER(SEARCH("ALUMINIO",INVENTARIO!C7)),"ALU", IF(ISNUMBER(SEARCH("CANAL",INVENTARIO!C7)),"CAN", IF(ISNUMBER(SEARCH("ESCUADRA",INVENTARIO!C7)),"ESC", IF(ISNUMBER(SEARCH("SOPORTE",INVENTARIO!C7)),"SOP","OTR") )))))))))))))))))))))))))))))) -> LON | B7: =IF(ISNUMBER(SEARCH("CORTE",INVENTARIO!C7)),"COR", IF(ISNUMBER(SEARCH("CITYLIGHT",INVENTARIO!C7)),"CIT", IF(ISNUMBER(SEARCH("LINO",INVENTARIO!C7)),"LIN", IF(ISNUMBER(SEARCH("FABRIANO",INVENTARIO!C7)),"FAB", IF(ISNUMBER(SEARCH("SUNDANCE",INVENTARIO!C7)),"SUN", IF(ISNUMBER(SEARCH("SINTETICA",INVENTARIO!C7)),"SIN", IF(ISNUMBER(SEARCH("CONTROL",INVENTARIO!C7)),"CON", IF(ISNUMBER(SEARCH("TERMICO",INVENTARIO!C7)),"TER", IF(ISNUMBER(SEARCH("C-15",INVENTARIO!C7)),"C15", IF(ISNUMBER(SEARCH("C-20",INVENTARIO!C7)),"C20", IF(ISNUMBER(SEARCH("C-30",INVENTARIO!C7)),"C30", IF(ISNUMBER(SEARCH("C-40",INVENTARIO!C7)),"C40", IF(ISNUMBER(SEARCH("C-60",INVENTARIO!C7)),"C60", IF(ISNUMBER(SEARCH("C-80",INVENTARIO!C7)),"C80", IF(ISNUMBER(SEARCH("EQUIPO",INVENTARIO!C7)),"EQU", IF(ISNUMBER(SEARCH("FLOOR",INVENTARIO!C7)),"FLO", IF(ISNUMBER(SEARCH("CRISTAL",INVENTARIO!C7)),"CRI", IF(ISNUMBER(SEARCH(" SULFATADA",INVENTARIO!C18)),"SUL", IF(ISNUMBER(SEARCH("OPALINA",INVENTARIO!C7)),"OPA", IF(ISNUMBER(SEARCH("ADHERIBLE",INVENTARIO!C7)),"ADH", IF(ISNUMBER(SEARCH("MICRO",INVENTARIO!C7)),"MIC",""))))))))))))))))))))) | C7: =IF(ISNUMBER(SEARCH("PARED",INVENTARIO!C7)),"PAR", IF(ISNUMBER(SEARCH("FRONT",INVENTARIO!C7)),"FRO", IF(ISNUMBER(SEARCH("ALTA RESISTENCIA",INVENTARIO!C7)), "ALT-RES",IF(ISNUMBER(SEARCH("BACKLITE",INVENTARIO!C7)),"BAC", IF(ISNUMBER(SEARCH("MATE",INVENTARIO!C7)),"MAT", IF(ISNUMBER(SEARCH("MESH",INVENTARIO!C7)),"MES", IF(ISNUMBER(SEARCH("BRILLANTE",INVENTARIO!C7)),"BRI", IF(ISNUMBER(SEARCH("DELGADA",INVENTARIO!C7)),"DEL", IF(ISNUMBER(SEARCH("GRUESA",INVENTARIO!C7)),"GRU", IF(ISNUMBER(SEARCH("ESTATICO",INVENTARIO!C7)),"EST", IF(ISNUMBER(SEARCH("REFLECTIVO",INVENTARIO!C7)),"REF", IF(ISNUMBER(SEARCH("LX700",INVENTARIO!C7)),"LX7", IF(ISNUMBER(SEARCH("GRANDO",INVENTARIO!C7)),"GRA", IF(ISNUMBER(SEARCH("FB700",INVENTARIO!C7)),"FB7", IF(ISNUMBER(SEARCH("LX360",INVENTARIO!C7)),"LX3", IF(ISNUMBER(SEARCH("XEROX",INVENTARIO!C7)),"XER", IF(ISNUMBER(SEARCH("CEPILLADO",INVENTARIO!C7)),"CEP", IF(ISNUMBER(SEARCH("ESPEJO",INVENTARIO!C7)),"ESP", IF(ISNUMBER(SEARCH("10 PTS",INVENTARIO!C7)),"10PT", IF(ISNUMBER(SEARCH("12 PTS",INVENTARIO!C7)),"12PT", IF(ISNUMBER(SEARCH("14 PTS",INVENTARIO!C7)),"14PT", IF(ISNUMBER(SEARCH("CLASICO",INVENTARIO!C7)),"CLA", "")))))))))))))))))))))) -> FRO | D7: =IF(ISNUMBER(SEARCH("GRAN FORMATO",INVENTARIO!C7)),"GRA-FOR", IF(ISNUMBER(SEARCH("CAMA PLANA",INVENTARIO!C7)),"CAM-PLA", IF(ISNUMBER(SEARCH("GRADO INGENIERIA",INVENTARIO!C7)),"GRA-ING", IF(ISNUMBER(SEARCH("130 GRS",INVENTARIO!C7)),"130GR", IF(ISNUMBER(SEARCH("150 GRS",INVENTARIO!C7)),"150GR", IF(ISNUMBER(SEARCH("185 GRS",INVENTARIO!C7)),"185GR", IF(ISNUMBER(SEARCH("200 GRS",INVENTARIO!C7)),"200GR", IF(ISNUMBER(SEARCH("250 GRS",INVENTARIO!C7)),"250GR", IF(ISNUMBER(SEARCH("300 GRS",INVENTARIO!C7)),"300GR", IF(ISNUMBER(SEARCH("350 GRS",INVENTARIO!C7)),"350GR", IF(ISNUMBER(SEARCH("18 OZ",INVENTARIO!C7)),"18OZ", IF(ISNUMBER(SEARCH("15 OZ",INVENTARIO!C7)),"15OZ", IF(OR(ISNUMBER(SEARCH("13 OZ",INVENTARIO!C7)),ISNUMBER(SEARCH("13 ONZAS",INVENTARIO!C7))),"13OZ", IF(OR(ISNUMBER(SEARCH("9 OZ",INVENTARIO!C7)),ISNUMBER(SEARCH("9 ONZAS",INVENTARIO!C7))),"09OZ", IF(ISNUMBER(SEARCH("DOBLE CARA",INVENTARIO!C7)),"DOB-CAR", ""))))))))))))))) -> 13OZ | E7: =IF(OR(ISNUMBER(SEARCH("TRANSPARENTE",INVENTARIO!C7)),ISNUMBER(SEARCH("TRANSPARENTES",INVENTARIO!C7))),"TRA", IF(OR(ISNUMBER(SEARCH("BLANCO",INVENTARIO!C7)),ISNUMBER(SEARCH("BCO",INVENTARIO!C7))),"BLA", IF(ISNUMBER(SEARCH("FOTOGRAFICO",INVENTARIO!C7)),"FOT", IF(ISNUMBER(SEARCH("MARFIL",INVENTARIO!C7)),"MAR", IF(ISNUMBER(SEARCH("VERDE",INVENTARIO!C7)),"VER", IF(ISNUMBER(SEARCH("MORADO",INVENTARIO!C7)),"MOR", IF(ISNUMBER(SEARCH("PLATA",INVENTARIO!C7)),"PLA", IF(ISNUMBER(SEARCH("ORO",INVENTARIO!C7)),"ORO", IF(ISNUMBER(SEARCH("AMARILLO",INVENTARIO!C7)),"AMA", IF(ISNUMBER(SEARCH("NARANJA",INVENTARIO!C7)),"NAR", IF(ISNUMBER(SEARCH("NEGRO",INVENTARIO!C7)),"NEG", IF(ISNUMBER(SEARCH("ROJO",INVENTARIO!C7)),"ROJ", IF(ISNUMBER(SEARCH("AZUL",INVENTARIO!C7)),"AZU",""))))))))))))) | F7: =IF(ISNUMBER(SEARCH("ARLON",INVENTARIO!C7)),"ARL", IF(ISNUMBER(SEARCH("SUNTHINKS",INVENTARIO!C7)),"SUN", IF(ISNUMBER(SEARCH("FRIO",INVENTARIO!C7)),"FRI", IF(ISNUMBER(SEARCH("CALIDO",INVENTARIO!C7)),"CAL", IF(ISNUMBER(SEARCH("CEPILLADO",INVENTARIO!C7)),"CEP", IF(ISNUMBER(SEARCH("ESPEJO",INVENTARIO!C7)),"ESP", "")))))) | G7: =IF(ISNUMBER(SEARCH("LATEX",INVENTARIO!C7)),"LAT", IF(ISNUMBER(SEARCH("RESP. NEGRO",INVENTARIO!C7)),"RES-NEG", IF(ISNUMBER(SEARCH("RESPALDO CAFE",INVENTARIO!C7)),"RES-CAF", IF(ISNUMBER(SEARCH("RESPALDO GRIS",INVENTARIO!C7)),"RES-GRI", IF(ISNUMBER(SEARCH("OPTICO",INVENTARIO!C7)),"OPT", IF(ISNUMBER(SEARCH("1,2 MM",INVENTARIO!C7)),"1MM2", IF(ISNUMBER(SEARCH("2 MM",INVENTARIO!C7)),"2MM", IF(ISNUMBER(SEARCH("3 MM",INVENTARIO!C7)),"3MM", IF(ISNUMBER(SEARCH("4 MM",INVENTARIO!C7)),"4MM", IF(ISNUMBER(SEARCH("5 MM",INVENTARIO!C7)),"5MM", IF(ISNUMBER(SEARCH("6 MM",INVENTARIO!C7)),"6MM", IF(ISNUMBER(SEARCH("9 MM",INVENTARIO!C7)),"9MM", IF(ISNUMBER(SEARCH("10 MM",INVENTARIO!C7)),"10MM",""))))))))))))) | H7: =IF(ISNUMBER(SEARCH("GAMA BAJA",INVENTARIO!C7)),"GAM-BAJ", IF(ISNUMBER(SEARCH("OPTIMIZADOR",INVENTARIO!C7)),"OPT", IF(ISNUMBER(SEARCH("OVERCOAT",INVENTARIO!C7)),"OVE", IF(ISNUMBER(SEARCH("WHITE",INVENTARIO!C7)),"WHI", IF(ISNUMBER(SEARCH("LIGHT CYAN",INVENTARIO!C7)),"LIG-CYA", IF(ISNUMBER(SEARCH("CYAN",INVENTARIO!C7)),"CYA", IF(ISNUMBER(SEARCH("LIGHT MAGENTA",INVENTARIO!C7)),"LIG-MAG", IF(ISNUMBER(SEARCH("MAGENTA",INVENTARIO!C7)),"MAG", IF(ISNUMBER(SEARCH("BLACK",INVENTARIO!C7)),"BLA", IF(ISNUMBER(SEARCH("YELLOW",INVENTARIO!C7)),"YEL", IF(ISNUMBER(SEARCH("2 DIODOS",INVENTARIO!C7)),"2DI", IF(ISNUMBER(SEARCH("3 DIODOS",INVENTARIO!C7)),"3DI", IF(OR(ISNUMBER(SEARCH("TRASLUCIDO",INVENTARIO!C7)),ISNUMBER(SEARCH("TRANSLUCIDO",INVENTARIO!C7))),"TRA", ""))))))))))))) | I7: =IF(ISNUMBER(SEARCH("SILED",INVENTARIO!C7)),"SI", IF(ISNUMBER(SEARCH("SYDEMEX",INVENTARIO!C7)),"SY", IF(ISNUMBER(SEARCH("ROHS",INVENTARIO!C7)),"RO", IF(ISNUMBER(SEARCH("RISHANG",INVENTARIO!C7)),"RS", IF(ISNUMBER(SEARCH("VYG",INVENTARIO!C7)),"VYG", IF(ISNUMBER(SEARCH("COLED",INVENTARIO!C7)),"CO",""))))))
